Workbook

Sheet Hall of Fame
A1: Saturday Xmas Challenge Cup | J1: The Cherry Lodge Trophy | S1: The Morrow Masters
A4: 2006 | E4: Kevin Fletcher | J4: 2006 | S4: 2006
A6: 2007 | E6: Graham Mitchell | J6: 2007 | S6: 2007
A8: 2008 | D8: 44 | E8: Ian Roy | J8: 2008 | M8: 27 | N8: Michael Folb | S8: 2008
A10: 2009 | D10: 39 | E10: Alan Dossett | J10: 2009 | M10: 24 | N10: Paul Mason | S10: 2009
A12: =A10+1 -> 2010 | D12: 40 | E12: Chris Bowden | J12: =J10+1 -> 2010 | M12: 25 | N12: Jeffery Millins | S12: =S10+1 -> 2010
A14: =A12+1 -> 2011 | D14: 37 | E14: Ray Hasler | J14: =J12+1 -> 2011 | M14: 24 | N14: Ivan Hook | S14: =S12+1 -> 2011
A16: =A14+1 -> 2012 | D16: 42 | E16: Rick Morrison | J16: =J14+1 -> 2012 | M16: 22 | N16: Peter Bucknell | S16: =S14+1 -> 2012
A18: =A16+1 -> 2013 | D18: 37 | E18: Terry Walker | J18: =J16+1 -> 2013 | M18: 21 | N18: Phil Cook | S18: =S16+1 -> 2013
A20: =A18+1 -> 2014 | D20: 41 | E20: Norman Rose | J20: =J18+1 -> 2014 | M20: 20 | N20: Andy Thompson | S20: =S18+1 -> 2014
A22: =A20+1 -> 2015 | D22: 42 | E22: Scott Lineard | J22: =J20+1 -> 2015 | N22: Pat Coleman | S22: =S20+1 -> 2015
A24: =A22+1 -> 2016 | E24: No contest due to fog | J24: =J22+1 -> 2016 | N24: No contest due to fog | S24: =S22+1 -> 2016
A26: =A24+1 -> 2017 | D26: 37 | E26: Graham Cole | J26: =J24+1 -> 2017 | M26: 20 | N26: Andy Thompson & Rob Harley | S26: =S24+1 -> 2017 | W26: Richard Minnis
A28: =A26+1 -> 2018 | D28: 46 | E28: Graham Cole | J28: =J26+1 -> 2018 | M28: 20 | N28: Dan Hunt | S28: =S26+1 -> 2018
A30: =A28+1 -> 2019 | E30: No contest due to waterlogged course | J30: =J28+1 -> 2019 | N30: No contest due to waterlogged course | S30: =S28+1 -> 2019 | W30: Phil Cook
A32: =A30+1 -> 2020 | E32: No contest due to Covid | J32: =J30+1 -> 2020 | N32: No contest due to Covid | S32: =S30+1 -> 2020
A34: =A32+1 -> 2021 | D34: 35 | E34: Phil Cook, Dickie Moxon, Dan Callingham & Steve Wheeler | J34: =J32+1 -> 2021 | N34: No contested | S34: =S32+1 -> 2021
A36: =A34+1 -> 2022 | D36: 40 | E36: Stuart Gay, Andy Thompson | J36: =J34+1 -> 2022 | M36: 24 | N36: Steve Wheeler | S36: =S34+1 -> 2022
A38: =A36+1 -> 2023 | E38: No contest due to waterlogged course | J38: =J36+1 -> 2023 | N38: Mike Forrest (Based on Order of Merit) | S38: =S36+1 -> 2023 | W38: Paul Clarke
A40: 2024 | J40: 2024 | M40: 0 | N40: Ross Fraser (Was DQ'd from the day) | S40: 2024
A42: 2025 | D42: 36 | E42: Chris Smith (Based on Arm Wrestle decider) | J42: 2025 | M42: 18 | N42: Archie Fraser | S42: 2025

Sheet Name List
D3: Scoring | F3: Date
D4: average | F4: 46025 | H4: Entry | I4: 5
D5: 2 from 3 | F5: =F4+7 -> 46032
B6: Stuart Anderson | D6: all scores count | F6: =F5+7 -> 46039
B7: Max Ball | D7: individual | F7: =F6+7 -> 46046
B8: Harley Bishop | D8: None | F8: =F7+7 -> 46053
B9: Chris Burroughs | F9: =F8+7 -> 46060
B10: George Burton | F10: =F9+7 -> 46067
B11: Tom Burton | F11: =F10+7 -> 46074
B12: Mike Chubb | F12: =F11+7 -> 46081
B13: George Clarke | F13: =F12+7 -> 46088
B14: Paul Clarke | D14: Format | F14: =F13+7 -> 46095
B15: Martin Coomber | D15: Swindle | F15: =F14+7 -> 46102
B16: Dominic Coughlin | D16: Monthly Stableford | F16: =F15+7 -> 46109
B17: Gareth Davies | D17: Monthly Medal | F17: =F16+7 -> 46116
B18: Peter Donovan | D18: Club Competition | F18: =F17+7 -> 46123
B19: James Dunn | F19: =F18+7 -> 46130
B20: Gordon Fielding | F20: =F19+7 -> 46137
B21: Paul Fitzgerald | F21: =F20+7 -> 46144
B22: Ben Fleet | F22: =F21+7 -> 46151
B23: Mike Forrest | F23: =F22+7 -> 46158
B24: Tony Forsyth-James | F24: =F23+7 -> 46165
B25: Archie Fraser | F25: =F24+7 -> 46172
B26: Ross Fraser | F26: =F25+7 -> 46179
B27: Nick Garner | F27: =F26+7 -> 46186
B28: Stuart Gay | F28: =F27+7 -> 46193
B29: Jordan Hall | F29: =F28+7 -> 46200
B30: Gary Hall | F30: =F29+7 -> 46207
... B55: Rory Thompson | F55: =F54+7 -> 46382
B56: Sonny Thompson
B57: Kevin Tribley
B58: Russell Turner
B59: Peter Vallely
B60: Ryan Vaughan
B61: Jason Wale
B62: Terry Walker
B63: Finn Wheeler
B64: Steve Wheeler
B65: Brad Whitehead
B66: Dave Woodget
...

Sheet Scores and stats
QT1: Across All Play Types | QY1: Norm + Monthlys | RK1: Norm + Monthlys
C2: =$A$2+1 -> 1 | F2: Eagles | G2: Birdies | H2: Pars | I2: Blobs | J2: Entry fee | L2: =$C$2+1 -> 2 | O2: Eagles | P2: Birdies | Q2: Pars | R2: Blobs | S2: Entry fee | U2: 3 | X2: Eagles | Y2: Birdies | Z2: Pars | AA2: Blobs | AB2: Entry fee | AD2: 4 | AG2: Eagles | AH2: Birdies | AI2: Pars | AJ2: Blobs | AK2: Entry fee | AM2: =AD2+1 -> 5 | AP2: Eagles | AQ2: Birdies | AR2: Pars | AS2: Blobs | AT2: Entry fee | AV2: =AM2+1 -> 6 | AY2: Eagles | AZ2: Birdies | BA2: Pars | BB2: Blobs | BC2: Entry fee | BE2: =AV2+1 -> 7 | BH2: Eagles | BI2: Birdies | BJ2: Pars | BK2: Blobs | BL2: Entry fee | BN2: =BE2+1 -> 8 | BQ2: Eagles | BR2: Birdies | BS2: Pars | BT2: Blobs | BU2: Entry fee | BW2: =BN2+1 -> 9 | BZ2: Eagles | CA2: Birdies | CB2: Pars | CC2: Blobs | CD2: Entry fee | CF2: =BW2+1 -> 10 | CI2: Eagles | CJ2: Birdies | CK2: Pars | CL2: Blobs | CM2: Entry fee | CO2: =CF2+1 -> 11 | CR2: Eagles | CS2: Birdies | CT2: Pars | CU2: Blobs | CV2: Entry fee | CX2: =CO2+1 -> 12 | DA2: Eagles | DB2: Birdies | DC2: Pars | DD2: Blobs | DE2: Entry fee | DG2: =CX2+1 -> 13 | DJ2: Eagles | DK2: Birdies | DL2: Pars | DM2: Blobs | DN2: Entry fee | DP2: =DG2+1 -> 14 | DS2: Eagles | DT2: Birdies | DU2: Pars | DV2: Blobs | DW2: Entry fee | DY2: =DP2+1 -> 15 | EB2: Eagles | EC2: Birdies | ED2: Pars | EE2: Blobs | EF2: Entry fee | EH2: =DY2+1 -> 16 | EK2: Eagles | EL2: Birdies | EM2: Pars | EN2: Blobs | EO2: Entry fee | EQ2: =EH2+1 -> 17 | ET2: Eagles | EU2: Birdies | EV2: Pars | EW2: Blobs | EX2: Entry fee | EZ2: =EQ2+1 -> 18 | FC2: Eagles | FD2: Birdies | FE2: Pars | FF2: Blobs | FG2: Entry fee | FI2: =EZ2+1 -> 19 | FL2: Eagles | FM2: Birdies | FN2: Pars | FO2: Blobs | FP2: Entry fee | FR2: =FI2+1 -> 20 | FU2: Eagles | FV2: Birdies | FW2: Pars | FX2: Blobs | FY2: Entry fee | GA2: =FR2+1 -> 21 | GD2: Eagles | GE2: Birdies | GF2: Pars | GG2: Blobs | GH2: Entry fee | GJ2: =GA2+1 -> 22 | GM2: Eagles | GN2: Birdies | GO2: Pars | GP2: Blobs | GQ2: Entry fee | GS2: =GJ2+1 -> 23 | GV2: Eagles | GW2: Birdies | GX2: Pars | GY2: Blobs | GZ2: Entry fee | HB2: =GS2+1 -> 24 | HE2: Eagles | HF2: Birdies | HG2: Pars | HH2: Blobs | HI2: Entry fee | HK2: =HB2+1 -> 25 | HN2: Eagles | HO2: Birdies | HP2: Pars | HQ2: Blobs | HR2: Entry fee | HT2: =HK2+1 -> 26 | HW2: Eagles | HX2: Birdies | HY2: Pars | HZ2: Blobs | IA2: Entry fee | IC2: =HT2+1 -> 27 | IF2: Eagles | IG2: Birdies | IH2: Pars | II2: Blobs | IJ2: Entry fee | IL2: =IC2+1 -> 28 | IO2: Eagles | IP2: Birdies | IQ2: Pars | IR2: Blobs | IS2: Entry fee | IU2: =IL2+1 -> 29 | IX2: Eagles | IY2: Birdies | IZ2: Pars | JA2: Blobs | JB2: Entry fee | JD2: =IU2+1 -> 30 | JG2: Eagles | JH2: Birdies | JI2: Pars | JJ2: Blobs | JK2: Entry fee | JM2: =JD2+1 -> 31 | JP2: Eagles | JQ2: Birdies | JR2: Pars | JS2: Blobs | JT2: Entry fee | JV2: =JM2+1 -> 32 | JY2: Eagles | JZ2: Birdies | KA2: Pars | KB2: Blobs | KC2: Entry fee | KE2: =JV2+1 -> 33 | KH2: Eagles | KI2: Birdies | KJ2: Pars | KK2: Blobs | KL2: Entry fee | KN2: =KE2+1 -> 34 | KQ2: Eagles | KR2: Birdies | KS2: Pars | KT2: Blobs | KU2: Entry fee | KW2: =KN2+1 -> 35 | KZ2: Eagles | LA2: Birdies | LB2: Pars | LC2: Blobs | LD2: Entry fee | LF2: =KW2+1 -> 36 | LI2: Eagles | LJ2: Birdies | LK2: Pars | LL2: Blobs | LM2: Entry fee | LO2: =LF2+1 -> 37 | LR2: Eagles | LS2: Birdies | LT2: Pars | LU2: Blobs | LV2: Entry fee | LX2: =LO2+1 -> 38 | MA2: Eagles | MB2: Birdies | MC2: Pars | MD2: Blobs | ME2: Entry fee | MG2: =LX2+1 -> 39 | MJ2: Eagles | MK2: Birdies | ML2: Pars | MM2: Blobs | MN2: Entry fee | MP2: =MG2+1 -> 40 | MS2: Eagles | MT2: Birdies | MU2: Pars | MV2: Blobs | MW2: Entry fee | MY2: =MP2+1 -> 41 | NB2: Eagles | NC2: Birdies | ND2: Pars | NE2: Blobs | NF2: Entry fee | NH2: =MY2+1 -> 42 | NK2: Eagles | NL2: Birdies | NM2: Pars | NN2: Blobs | NO2: Entry fee | NQ2: =NH2+1 -> 43 | NT2: Eagles | NU2: Birdies | NV2: Pars | NW2: Blobs | NX2: Entry fee | NZ2: =NQ2+1 -> 44 | OC2: Eagles | OD2: Birdies | OE2: Pars | OF2: Blobs | OG2: Entry fee | OI2: =NZ2+1 -> 45 | OL2: Eagles | OM2: Birdies | ON2: Pars | OO2: Blobs | OP2: Entry fee | OR2: =OI2+1 -> 46 | OU2: Eagles | OV2: Birdies | OW2: Pars | OX2: Blobs | OY2: Entry fee | PA2: =OR2+1 -> 47 | PD2: Eagles | PE2: Birdies | PF2: Pars | PG2: Blobs | PH2: Entry fee | PJ2: =PA2+1 -> 48 | PM2: Eagles | PN2: Birdies | PO2: Pars | PP2: Blobs | PQ2: Entry fee | PS2: =PJ2+1 -> 49 | PV2: Eagles | PW2: Birdies | PX2: Pars | PY2: Blobs | PZ2: Entry fee | QB2: =PS2+1 -> 50 | QE2: Eagles | QF2: Birdies | QG2: Pars | QH2: Blobs | QI2: Entry fee | QK2: =QB2+1 -> 51 | QN2: Eagles | QO2: Birdies | QP2: Pars | QQ2: Blobs | QR2: Entry fee | QT2: Eagles | QU2: Birdies | QV2: Pars | QW2: Blobs | QY2: Stablefords played | RA2: Best Swindle Stableford Front 9 | RB2: Best Swindle Stableford Back 9 | RC2: Best Swindle stableford score | RD2: Worst Swindle Stableford Front 9 | RE2: Worst Swindle Stableford Back 9 | RF2: Worst Swindle stableford score | RH2: Best Monthly stableford score | RI2: Worst Monthly stableford score | RK2: Average stableford score | RM2: Best Medal score | RN2: Worst Medal score | RP2: Medals played
C3: 46025 | L3: 46032 | U3: 46039 | AD3: 46046 | AM3: =AD3+7 -> 46053 | AV3: =AM3+7 -> 46060 | BE3: =AV3+7 -> 46067 | BN3: =BE3+7 -> 46074 | BW3: =BN3+7 -> 46081 | CF3: =BW3+7 -> 46088 | CO3: =CF3+7 -> 46095 | CX3: =CO3+7 -> 46102 | DG3: =CX3+7 -> 46109 | DP3: =DG3+7 -> 46116 | DY3: =DP3+7 -> 46123 | EH3: =DY3+7 -> 46130 | EQ3: =EH3+7 -> 46137 | EZ3: =EQ3+7 -> 46144 | FI3: =EZ3+7 -> 46151 | FR3: =FI3+7 -> 46158 | GA3: =FR3+7 -> 46165 | GJ3: =GA3+7 -> 46172 | GS3: =GJ3+7 -> 46179 | HB3: =GS3+7 -> 46186 | HK3: =HB3+7 -> 46193 | HT3: =HK3+7 -> 46200 | IC3: =HT3+7 -> 46207 | IL3: =IC3+7 -> 46214 | IU3: =IL3+7 -> 46221 | JD3: =IU3+7 -> 46228 | JM3: =JD3+7 -> 46235 | JV3: =JM3+7 -> 46242 | KE3: =JV3+7 -> 46249 | KN3: =KE3+7 -> 46256 | KW3: =KN3+7 -> 46263 | LF3: =KW3+7 -> 46270 | LO3: =LF3+7 -> 46277 | LX3: =LO3+7 -> 46284 | MG3: =LX3+7 -> 46291 | MP3: =MG3+7 -> 46298 | MY3: =MP3+7 -> 46305 | NH3: =MY3+7 -> 46312 | NQ3: =NH3+7 -> 46319 | NZ3: 46326 | OI3: =NZ3+7 -> 46333 | OR3: =OI3+7 -> 46340 | PA3: =OR3+7 -> 46347 | PJ3: =PA3+7 -> 46354 | PS3: =PJ3+7 -> 46361 | QB3: =PS3+7 -> 46368 | QK3: =QB3+7 -> 46375
C4: Swindle | L4: Swindle | U4: Monthly Stableford | AD4: Swindle | AM4: Swindle | AV4: Monthly Stableford | BE4: Swindle | BN4: Swindle | BW4: Swindle | CF4: Club Competition | CO4: Monthly Stableford | CX4: Swindle | DG4: Swindle | DP4: Swindle | DY4: Swindle | EH4: Swindle | EQ4: Monthly Medal | EZ4: Club Competition | FI4: Swindle | FR4: Swindle | GA4: Swindle | GJ4: Swindle | GS4: Club Competition | HB4: Swindle | HK4: Monthly Stableford | HT4: Club Competition | IC4: Monthly Medal | IL4: Swindle | IU4: Swindle | JD4: Swindle | JM4: Swindle | JV4: Swindle | KE4: Swindle | KN4: Club Competition | KW4: Swindle | LF4: Monthly Stableford | LO4: Swindle | LX4: Swindle | MG4: Swindle | MP4: Swindle | MY4: Swindle | NH4: Swindle | NQ4: Swindle | NZ4: Monthly Stableford | OI4: Swindle | OR4: Monthly Stableford | PA4: Swindle | PJ4: Club Competition | PS4: Swindle | QB4: Monthly Stableford | QK4: Club Competition
A5: Name | C5: Front | D5: Back | E5: Score | L5: Front | M5: Back | N5: Score | U5: Front | V5: Back | W5: Score | AD5: Front | AE5: Back | AF5: Score | AM5: Front | AN5: Back | AO5: Score | AV5: Front | AW5: Back | AX5: Score | BE5: Front | BF5: Back | BG5: Score | BN5: Front | BO5: Back | BP5: Score | BW5: Front | BX5: Back | BY5: Score | CF5: Front | CG5: Back | CH5: Score | CO5: Front | CP5: Back | CQ5: Score | CX5: Front | CY5: Back | CZ5: Score | DG5: Front | DH5: Back | DI5: Score | DP5: Front | DQ5: Back | DR5: Score | DY5: Front | DZ5: Back | EA5: Score | EH5: Front | EI5: Back | EJ5: Score | EQ5: Front | ER5: Back | ES5: Score | EZ5: Front | FA5: Back | FB5: Score | FI5: Front | FJ5: Back | FK5: Score | FR5: Front | FS5: Back | FT5: Score | GA5: Front | GB5: Back | GC5: Score | GJ5: Front | GK5: Back | GL5: Score | GS5: Front | GT5: Back | GU5: Score | HB5: Front | HC5: Back | HD5: Score | HK5: Front | HL5: Back | HM5: Score | HT5: Front | HU5: Back | HV5: Score | IC5: Front | ID5: Back | IE5: Score | IL5: Front | IM5: Back | IN5: Score | IU5: Front | IV5: Back | IW5: Score | JD5: Front | JE5: Back | JF5: Score | JM5: Front | JN5: Back | JO5: Score | JV5: Front | JW5: Back | JX5: Score | KE5: Front | KF5: Back | KG5: Score | KN5: Front | KO5: Back | KP5: Score | KW5: Front | KX5: Back | KY5: Score | LF5: Front | LG5: Back | LH5: Score | LO5: Front | LP5: Back | LQ5: Score | LX5: Front | LY5: Back | LZ5: Score | MG5: Front | MH5: Back | MI5: Score | MP5: Front | MQ5: Back | MR5: Score | MY5: Front | MZ5: Back | NA5: Score | NH5: Front | NI5: Back | NJ5: Score | NQ5: Front | NR5: Back | NS5: Score | NZ5: Front | OA5: Back | OB5: Score | OI5: Front | OJ5: Back | OK5: Score | OR5: Front | OS5: Back | OT5: Score | PA5: Front | PB5: Back | PC5: Score | PJ5: Front | PK5: Back | PL5: Score | PS5: Front | PT5: Back | PU5: Score | QB5: Front | QC5: Back | QD5: Score | QK5: Front | QL5: Back | QM5: Score
A6: ='Name List'!B6 -> Stuart Anderson | E6: =IF(C6=0,"",C6+D6) | J6: =IF(E6="","",'Name List'!$I$4) | N6: =IF(L6=0,"",L6+M6) | S6: =IF(N6="","",'Name List'!$I$4) | W6: =IF(U6=0,"",U6+V6) | AB6: =IF(W6="","",'Name List'!$I$4) | AF6: =IF(AD6=0,"",AD6+AE6) | AK6: =IF(AF6="","",'Name List'!$I$4) | AO6: =IF(AM6=0,"",AM6+AN6) | AT6: =IF(AO6="","",'Name List'!$I$4) | AX6: =IF(AV6=0,"",AV6+AW6) | BC6: =IF(AX6="","",'Name List'!$I$4) | BG6: =IF(BE6=0,"",BE6+BF6) | BL6: =IF(BG6="","",'Name List'!$I$4) | BP6: =IF(BN6=0,"",BN6+BO6) | BU6: =IF(BP6="","",'Name List'!$I$4) | BY6: =IF(BW6=0,"",BW6+BX6) | CD6: =IF(BY6="","",'Name List'!$I$4) | CH6: =IF(CF6=0,"",CF6+CG6) | CM6: =IF(CH6="","",'Name List'!$I$4) | CQ6: =IF(CO6=0,"",CO6+CP6) | CV6: =IF(CQ6="","",'Name List'!$I$4) | CZ6: =IF(CX6=0,"",CX6+CY6) | DE6: =IF(CZ6="","",'Name List'!$I$4) | DI6: =IF(DG6=0,"",DG6+DH6) | DN6: =IF(DI6="","",'Name List'!$I$4) | DR6: =IF(DP6=0,"",DP6+DQ6) | DW6: =IF(DR6="","",'Name List'!$I$4) | EA6: =IF(DY6=0,"",DY6+DZ6) | EF6: =IF(EA6="","",'Name List'!$I$4) | EJ6: =IF(EH6=0,"",EH6+EI6) | EO6: =IF(EJ6="","",'Name List'!$I$4) | EX6: =IF(ES6="","",'Name List'!$I$4) | FB6: =IF(EZ6=0,"",EZ6+FA6) | FG6: =IF(FB6="","",'Name List'!$I$4) | FK6: =IF(FI6=0,"",FI6+FJ6) | FP6: =IF(FK6="","",'Name List'!$I$4) | FT6: =IF(FR6=0,"",FR6+FS6) | FY6: =IF(FT6="","",'Name List'!$I$4) | GC6: =IF(GA6=0,"",GA6+GB6) | GH6: =IF(GC6="","",'Name List'!$I$4) | GL6: =IF(GJ6=0,"",GJ6+GK6) | GQ6: =IF(GL6="","",'Name List'!$I$4) | GU6: =IF(GS6=0,"",GS6+GT6) | GZ6: =IF(GU6="","",'Name List'!$I$4) | HD6: =IF(HB6=0,"",HB6+HC6) | HI6: =IF(HD6="","",'Name List'!$I$4) | HM6: =IF(HK6=0,"",HK6+HL6) | HR6: =IF(HM6="","",'Name List'!$I$4) | HV6: =IF(HT6=0,"",HT6+HU6) | IA6: =IF(HV6="","",'Name List'!$I$4) | IJ6: =IF(IE6="","",'Name List'!$I$4) | IN6: =IF(IL6=0,"",IL6+IM6) | IS6: =IF(IN6="","",'Name List'!$I$4) | IW6: =IF(IU6=0,"",IU6+IV6) | JB6: =IF(IW6="","",'Name List'!$I$4) | JF6: =IF(JD6=0,"",JD6+JE6) | JK6: =IF(JF6="","",'Name List'!$I$4) | JO6: =IF(JM6=0,"",JM6+JN6) | JT6: =IF(JO6="","",'Name List'!$I$4) | JX6: =IF(JV6=0,"",JV6+JW6) | KC6: =IF(JX6="","",'Name List'!$I$4) | KG6: =IF(KE6=0,"",KE6+KF6) | KL6: =IF(KG6="","",'Name List'!$I$4) | KP6: =IF(KN6=0,"",KN6+KO6) | KU6: =IF(KP6="","",'Name List'!$I$4) | KY6: =IF(KW6=0,"",KW6+KX6) | LD6: =IF(KY6="","",'Name List'!$I$4) | LH6: =IF(LF6=0,"",LF6+LG6) | LM6: =IF(LH6="","",'Name List'!$I$4) | LQ6: =IF(LO6=0,"",LO6+LP6) | LV6: =IF(LQ6="","",'Name List'!$I$4) | LZ6: =IF(LX6=0,"",LX6+LY6) | ME6: =IF(LZ6="","",'Name List'!$I$4) | MI6: =IF(MG6=0,"",MG6+MH6) | MN6: =IF(MI6="","",'Name List'!$I$4) | MR6: =IF(MP6=0,"",MP6+MQ6) | MW6: =IF(MR6="","",'Name List'!$I$4) | NA6: =IF(MY6=0,"",MY6+MZ6) | NF6: =IF(NA6="","",'Name List'!$I$4) | NJ6: =IF(NH6=0,"",NH6+NI6) | NO6: =IF(NJ6="","",'Name List'!$I$4) | NS6: =IF(NQ6=0,"",NQ6+NR6) | NX6: =IF(NS6="","",'Name List'!$I$4) | OB6: =IF(NZ6=0,"",NZ6+OA6) | OG6: =IF(OB6="","",'Name List'!$I$4) | OK6: =IF(OI6=0,"",OI6+OJ6) | OP6: =IF(OK6="","",'Name List'!$I$4) | OT6: =IF(OR6=0,"",OR6+OS6) | OY6: =IF(OT6="","",'Name List'!$I$4) | PC6: =IF(PA6=0,"",PA6+PB6) | PH6: =IF(PC6="","",'Name List'!$I$4) | PL6: =IF(PJ6=0,"",PJ6+PK6) | PQ6: =IF(PL6="","",'Name List'!$I$4) | PU6: =IF(PS6=0,"",PS6+PT6) | PZ6: =IF(PU6="","",'Name List'!$I$4) | QD6: =IF(QB6=0,"",QB6+QC6) | QI6: =IF(QD6="","",'Name List'!$I$4) | QM6: =IF(QK6=0,"",QK6+QL6) | QR6: =IF(QM6="","",'Name List'!$I$4) | QT6: =SUM(F6+O6+X6+AG6+AP6+AY6+BH6+BQ6+BZ6+CI6+CR6+DA6+DJ6+DS6+EB6+EK6+ET6+FC6+FL6+FU6+GD6+GM6+GV6+HE6+HN6+HW6+IF6+IO6+IX6+JG6+JP6+JY6+KH6+KQ6+KZ6+LI6+LR6+MA6+MJ6+MS6+NB6+NK6+NT6+OC6+OL6+OU6+PD6+PM6+PV6+QE6+QN6) -> 0 | QU6: =SUM(G6+P6+Y6+AH6+AQ6+AZ6+BI6+BR6+CA6+CJ6+CS6+DB6+DK6+DT6+EC6+EL6+EU6+FD6+FM6+FV6+GE6+GN6+GW6+HF6+HO6+HX6+IG6+IP6+IY6+JH6+JQ6+JZ6+KI6+KR6+LA6+LJ6+LS6+MB6+MK6+MT6+NC6+NL6+NU6+OD6+OM6+OV6+PE6+PN6+PW6+QF6+QO6) -> 0 | QV6: =SUM(H6+Q6+Z6+AI6+AR6+BA6+BJ6+BS6+CB6+CK6+CT6+DC6+DL6+DU6+ED6+EM6+EV6+FE6+FN6+FW6+GF6+GO6+GX6+HG6+HP6+HY6+IH6+IQ6+IZ6+JI6+JR6+KA6+KJ6+KS6+LB6+LK6+LT6+MC6+ML6+MU6+ND6+NM6+NV6+OE6+ON6+OW6+PF6+PO6+PX6+QG6+QP6) -> 0 | QW6: =SUM(I6+R6+AA6+AJ6+AS6+BB6+BK6+BT6+CC6+CL6+CU6+DD6+DM6+DV6+EE6+EN6+EW6+FF6+FO6+FX6+GG6+GP6+GY6+HH6+HQ6+HZ6+II6+IR6+JA6+JJ6+JS6+KB6+KK6+KT6+LC6+LL6+LU6+MD6+MM6+MV6+NE6+NN6+NW6+OF6+OO6+OX6+PG6+PP6+PY6+QH6+QQ6) -> 0 | QY6: =SUM(J6,S6,AB6,AK6,AT6,BC6,BL6,BU6,CD6,CM6,CV6,DE6,DN6,DW6,EF6,EO6,FP6,FY6,GH6,GQ6,HI6,HR6,IS6,JB6,JK6,JT6,KC6,KL6,KU6,LD6,LM6,LV6,ME6,MN6,MW6,NF6,NO6,NX6,OG6,OP6,OY6,PH6,PZ6)/5 -> 0 | RA6: =MAX(C6,L6,AD6,AM6,AV6,BN6,BW6,CF6,CX6,DG6,DP6,DY6,EH6,FI6,FR6,GA6,GJ6,HB6,IL6,IU6,JD6,JM6,JV6,KE6,KW6,LO6,LX6,MG6,MP6,MY6,NH6,NQ6,OI6,PA6,PS6) -> 0 | RB6: =MAX(D6,M6,AE6,AN6,AW6,BO6,BX6,CG6,CY6,DH6,DQ6,DZ6,EI6,FJ6,FS6,GB6,GK6,HC6,IM6,IV6,JE6,JN6,JW6,KF6,KX6,LP6,LY6,MH6,MQ6,MZ6,NI6,NR6,OJ6,PB6,PT6) -> 0 | RC6: =MAX(E6,N6,AF6,AO6,AX6,BP6,BY6,CH6,CZ6,DI6,DR6,EA6,EJ6,FK6,FT6,GC6,GL6,HD6,IN6,IW6,JF6,JO6,JX6,KG6,KY6,LQ6,LZ6,MI6,MR6,NA6,NJ6,NS6,OK6,PC6,PU6) -> 0 | RD6: =MIN(C6,L6,AD6,AM6,AV6,BN6,BW6,CF6,CX6,DG6,DP6,DY6,EH6,FI6,FR6,GA6,GJ6,HB6,IL6,IU6,JD6,JM6,JV6,KE6,KW6,LO6,LX6,MG6,MP6,MY6,NH6,NQ6,OI6,PA6,PS6) -> 0 | RE6: =MIN(D6,M6,AE6,AN6,AW6,BO6,BX6,CG6,CY6,DH6,DQ6,DZ6,EI6,FJ6,FS6,GB6,GK6,HC6,IM6,IV6,JE6,JN6,JW6,KF6,KX6,LP6,LY6,MH6,MQ6,MZ6,NI6,NR6,OJ6,PB6,PT6) -> 0 | RF6: =MIN(E6,N6,AF6,AO6,AX6,BP6,BY6,CH6,CZ6,DI6,DR6,EA6,EJ6,FK6,FT6,GC6,GL6,HD6,IN6,IW6,JF6,JO6,JX6,KG6,KY6,LQ6,LZ6,MI6,MR6,NA6,NJ6,NS6,OK6,PC6,PU6) -> 0 | RH6: =MAX(W6,BG6,CQ6,HM6,LH6,OB6,OT6) -> 0 | RI6: =MIN(W6,BG6,CQ6,HM6,LH6,OB6,OT6) -> 0 | RK6: =IFERROR(SUM(E6,N6,W6,AF6,AO6,AX6,BG6,BP6,BY6,CH6,CQ6,CZ6,DI6,DR6,EA6,EJ6,FK6,GC6,GL6,HD6,HM6,IN6,IW6,JF6,JO6,JX6,KG6,KY6,LH6,LQ6,LZ6,MI6,MR6,NA6,NJ6,NS6,OB6,OK6,OT6,PC6,)/QY6,0) -> 0 | RM6: =MAX(ES6,IE6) -> 0 | RN6: =MIN(ES6,IE6) -> 0 | RP6: =SUM(EX6,IJ6)/5 -> 0
A7: ='Name List'!B7 -> Max Ball | E7: =IF(C7=0,"",C7+D7) | J7: =IF(E7="","",'Name List'!$I$4) | W7: =IF(U7=0,"",U7+V7) | AB7: =IF(W7="","",'Name List'!$I$4) | AF7: =IF(AD7=0,"",AD7+AE7) | AK7: =IF(AF7="","",'Name List'!$I$4) | AO7: =IF(AM7=0,"",AM7+AN7) | AT7: =IF(AO7="","",'Name List'!$I$4) | AV7: 16 | AW7: 20 | AX7: =IF(AV7=0,"",AV7+AW7) -> 36 | AY7: 0 | AZ7: 1 | BA7: 10 | BB7: 1 | BC7: =IF(AX7="","",'Name List'!$I$4) -> 5 | BG7: =IF(BE7=0,"",BE7+BF7) | BL7: =IF(BG7="","",'Name List'!$I$4) | BW7: 20 | BX7: 21 | BY7: =IF(BW7=0,"",BW7+BX7) -> 41 | BZ7: 0 | CA7: 2 | CB7: 11 | CC7: 0 | CD7: =IF(BY7="","",'Name List'!$I$4) -> 5 | CF7: 14 | CG7: 20 | CH7: =IF(CF7=0,"",CF7+CG7) -> 34 | CI7: 0 | CJ7: 2 | CK7: 6 | CL7: 1 | CM7: =IF(CH7="","",'Name List'!$I$4) -> 5 | CO7: 13 | CP7: 22 | CQ7: =IF(CO7=0,"",CO7+CP7) -> 35 | CR7: 0 | CS7: 1 | CT7: 9 | CU7: 0 | CV7: =IF(CQ7="","",'Name List'!$I$4) -> 5 | CZ7: =IF(CX7=0,"",CX7+CY7) | DE7: =IF(CZ7="","",'Name List'!$I$4) | DG7: 17 | DH7: 18 | DI7: =IF(DG7=0,"",DG7+DH7) -> 35 | DJ7: 0 | DK7: 2 | DL7: 8 | DM7: 1 | DN7: =IF(DI7="","",'Name List'!$I$4) -> 5 | DR7: =IF(DP7=0,"",DP7+DQ7) | DW7: =IF(DR7="","",'Name List'!$I$4) | DY7: 18 | DZ7: 17 | EA7: =IF(DY7=0,"",DY7+DZ7) -> 35 | EB7: 0 | EC7: 1 | ED7: 9 | EE7: 0 | EF7: =IF(EA7="","",'Name List'!$I$4) -> 5 | EJ7: =IF(EH7=0,"",EH7+EI7) | EO7: =IF(EJ7="","",'Name List'!$I$4) | ES7: 83 | ET7: 0 | EU7: 0 | EV7: 8 | EX7: =IF(ES7="","",'Name List'!$I$4) -> 5 | FK7: =IF(FI7=0,"",FI7+FJ7) | FP7: =IF(FK7="","",'Name List'!$I$4) | FT7: =IF(FR7=0,"",FR7+FS7) | FY7: =IF(FT7="","",'Name List'!$I$4) | GC7: =IF(GA7=0,"",GA7+GB7) | GH7: =IF(GC7="","",'Name List'!$I$4) | GJ7: 20 | GK7: 15 | GL7: =IF(GJ7=0,"",GJ7+GK7) -> 35 | GM7: 0 | GN7: 1 | GO7: 12 | GP7: 2 | GQ7: =IF(GL7="","",'Name List'!$I$4) -> 5 | HB7: 19 | HC7: 18 | HD7: =IF(HB7=0,"",HB7+HC7) -> 37 | HE7: 0 | HF7: 3 | HG7: 7 | HH7: 1 | HI7: =IF(HD7="","",'Name List'!$I$4) -> 5 | HK7: 16 | HL7: 21 | HM7: =IF(HK7=0,"",HK7+HL7) -> 37 | HN7: 0 | HO7: 3 | HP7: 5 | HQ7: 1 | HR7: =IF(HM7="","",'Name List'!$I$4) -> 5 | IJ7: =IF(IE7="","",'Name List'!$I$4) | QR7: =IF(QM7="","",'Name List'!$I$4) | QT7: =SUM(F7+O7+X7+AG7+AP7+AY7+BH7+BQ7+BZ7+CI7+CR7+DA7+DJ7+DS7+EB7+EK7+ET7+FC7+FL7+FU7+GD7+GM7+GV7+HE7+HN7+HW7+IF7+IO7+IX7+JG7+JP7+JY7+KH7+KQ7+KZ7+LI7+LR7+MA7+MJ7+MS7+NB7+NK7+NT7+OC7+OL7+OU7+PD7+PM7+PV7+QE7+QN7) -> 0 | QU7: =SUM(G7+P7+Y7+AH7+AQ7+AZ7+BI7+BR7+CA7+CJ7+CS7+DB7+DK7+DT7+EC7+EL7+EU7+FD7+FM7+FV7+GE7+GN7+GW7+HF7+HO7+HX7+IG7+IP7+IY7+JH7+JQ7+JZ7+KI7+KR7+LA7+LJ7+LS7+MB7+MK7+MT7+NC7+NL7+NU7+OD7+OM7+OV7+PE7+PN7+PW7+QF7+QO7) -> 16 | QV7: =SUM(H7+Q7+Z7+AI7+AR7+BA7+BJ7+BS7+CB7+CK7+CT7+DC7+DL7+DU7+ED7+EM7+EV7+FE7+FN7+FW7+GF7+GO7+GX7+HG7+HP7+HY7+IH7+IQ7+IZ7+JI7+JR7+KA7+KJ7+KS7+LB7+LK7+LT7+MC7+ML7+MU7+ND7+NM7+NV7+OE7+ON7+OW7+PF7+PO7+PX7+QG7+QP7) -> 85 | QW7: =SUM(I7+R7+AA7+AJ7+AS7+BB7+BK7+BT7+CC7+CL7+CU7+DD7+DM7+DV7+EE7+EN7+EW7+FF7+FO7+FX7+GG7+GP7+GY7+HH7+HQ7+HZ7+II7+IR7+JA7+JJ7+JS7+KB7+KK7+KT7+LC7+LL7+LU7+MD7+MM7+MV7+NE7+NN7+NW7+OF7+OO7+OX7+PG7+PP7+PY7+QH7+QQ7) -> 7 | QY7: =SUM(J7,S7,AB7,AK7,AT7,BC7,BL7,BU7,CD7,CM7,CV7,DE7,DN7,DW7,EF7,EO7,FP7,FY7,GH7,GQ7,HI7,HR7,IS7,JB7,JK7,JT7,KC7,KL7,KU7,LD7,LM7,LV7,ME7,MN7,MW7,NF7,NO7,NX7,OG7,OP7,OY7,PH7,PZ7)/5 -> 9 | RA7: =MAX(C7,L7,AD7,AM7,AV7,BN7,BW7,CF7,CX7,DG7,DP7,DY7,EH7,FI7,FR7,GA7,GJ7,HK7,IL7,IU7,JD7,JM7,JV7,KE7,KW7,LO7,LX7,MG7,MP7,MY7,NH7,NQ7,OI7,PA7,PS7) -> 20 | RB7: =MAX(D7,M7,AE7,AN7,AW7,BO7,BX7,CG7,CY7,DH7,DQ7,DZ7,EI7,FJ7,FS7,GB7,GK7,HL7,IM7,IV7,JE7,JN7,JW7,KF7,KX7,LP7,LY7,MH7,MQ7,MZ7,NI7,NR7,OJ7,PB7,PT7) -> 21 | RC7: =MAX(E7,N7,AF7,AO7,AX7,BP7,BY7,CH7,CZ7,DI7,DR7,EA7,EJ7,FK7,FT7,GC7,GL7,HM7,IN7,IW7,JF7,JO7,JX7,KG7,KY7,LQ7,LZ7,MI7,MR7,NA7,NJ7,NS7,OK7,PC7,PU7) -> 41 | RD7: =MIN(C7,L7,AD7,AM7,AV7,BN7,BW7,CF7,CX7,DG7,DP7,DY7,EH7,FI7,FR7,GA7,GJ7,HK7,IL7,IU7,JD7,JM7,JV7,KE7,KW7,LO7,LX7,MG7,MP7,MY7,NH7,NQ7,OI7,PA7,PS7) -> 14 | RE7: =MIN(D7,M7,AE7,AN7,AW7,BO7,BX7,CG7,CY7,DH7,DQ7,DZ7,EI7,FJ7,FS7,GB7,GK7,HL7,IM7,IV7,JE7,JN7,JW7,KF7,KX7,LP7,LY7,MH7,MQ7,MZ7,NI7,NR7,OJ7,PB7,PT7) -> 15 | RF7: =MIN(E7,N7,AF7,AO7,AX7,BP7,BY7,CH7,CZ7,DI7,DR7,EA7,EJ7,FK7,FT7,GC7,GL7,HM7,IN7,IW7,JF7,JO7,JX7,KG7,KY7,LQ7,LZ7,MI7,MR7,NA7,NJ7,NS7,OK7,PC7,PU7) -> 34 | RH7: =MAX(W7,BG7,CQ7,HD7,LH7,OB7,OT7) -> 37 | RI7: =MIN(W7,BG7,CQ7,HD7,LH7,OB7,OT7) -> 35 | RK7: =IFERROR(SUM(E7,N7,W7,AF7,AO7,AX7,BG7,BP7,BY7,CH7,CQ7,CZ7,DI7,DR7,EA7,EJ7,FK7,GC7,GL7,HD7,HM7,IN7,IW7,JF7,JO7,JX7,KG7,KY7,LH7,LQ7,LZ7,MI7,MR7,NA7,NJ7,NS7,OB7,OK7,OT7,PC7,)/QY7,0) -> 36.111111 | RM7: =MAX(ES7,IE7) -> 83 | RN7: =MIN(ES7,IE7) -> 83 | RP7: =SUM(EX7,IJ7)/5 -> 1
A8: ='Name List'!B8 -> Harley Bishop | E8: =IF(C8=0,"",C8+D8) | J8: =IF(E8="","",'Name List'!$I$4) | U8: 12 | V8: 13 | W8: =IF(U8=0,"",U8+V8) -> 25 | X8: 0 | Y8: 0 | Z8: 2 | AA8: 2 | AB8: =IF(W8="","",'Name List'!$I$4) -> 5 | AD8: 18 | AE8: 9 | AF8: =IF(AD8=0,"",AD8+AE8) -> 27 | AG8: 0 | AH8: 1 | AI8: 4 | AJ8: 3 | AK8: =IF(AF8="","",'Name List'!$I$4) -> 5 | AM8: 13 | AN8: 16 | AO8: =IF(AM8=0,"",AM8+AN8) -> 29 | AP8: 0 | AQ8: 0 | AR8: 5 | AS8: 2 | AT8: =IF(AO8="","",'Name List'!$I$4) -> 5 | AX8: =IF(AV8=0,"",AV8+AW8) | BC8: =IF(AX8="","",'Name List'!$I$4) | BG8: =IF(BE8=0,"",BE8+BF8) | BL8: =IF(BG8="","",'Name List'!$I$4) | BY8: =IF(BW8=0,"",BW8+BX8) | CD8: =IF(BY8="","",'Name List'!$I$4) | CF8: 13 | CG8: 13 | CH8: =IF(CF8=0,"",CF8+CG8) -> 26 | CI8: 0 | CJ8: 1 | CK8: 3 | CL8: 5 | CM8: =IF(CH8="","",'Name List'!$I$4) -> 5 | CO8: 17 | CP8: 17 | CQ8: =IF(CO8=0,"",CO8+CP8) -> 34 | CR8: 0 | CS8: 1 | CT8: 7 | CU8: 3 | CV8: =IF(CQ8="","",'Name List'!$I$4) -> 5 | CZ8: =IF(CX8=0,"",CX8+CY8) | DE8: =IF(CZ8="","",'Name List'!$I$4) | DG8: 9 | DH8: 17 | DI8: =IF(DG8=0,"",DG8+DH8) -> 26 | DJ8: 0 | DK8: 0 | DL8: 5 | DM8: 4 | DN8: =IF(DI8="","",'Name List'!$I$4) -> 5 | DR8: =IF(DP8=0,"",DP8+DQ8) | DW8: =IF(DR8="","",'Name List'!$I$4) | EA8: =IF(DY8=0,"",DY8+DZ8) | EF8: =IF(EA8="","",'Name List'!$I$4) | EJ8: =IF(EH8=0,"",EH8+EI8) | EO8: =IF(EJ8="","",'Name List'!$I$4) | EX8: =IF(ES8="","",'Name List'!$I$4) | FI8: 16 | FJ8: 17 | FK8: =IF(FI8=0,"",FI8+FJ8) -> 33 | FL8: 0 | FM8: 1 | FN8: 4 | FO8: 0 | FP8: =IF(FK8="","",'Name List'!$I$4) -> 5 | FT8: =IF(FR8=0,"",FR8+FS8) | FY8: =IF(FT8="","",'Name List'!$I$4) | GC8: =IF(GA8=0,"",GA8+GB8) | GH8: =IF(GC8="","",'Name List'!$I$4) | GL8: =IF(GJ8=0,"",GJ8+GK8) | GQ8: =IF(GL8="","",'Name List'!$I$4) | HD8: =IF(HB8=0,"",HB8+HC8) | HI8: =IF(HD8="","",'Name List'!$I$4) | HM8: =IF(HK8=0,"",HK8+HL8) | HR8: =IF(HM8="","",'Name List'!$I$4) | IJ8: =IF(IE8="","",'Name List'!$I$4) | QR8: =IF(QM8="","",'Name List'!$I$4) | QT8: =SUM(F8+O8+X8+AG8+AP8+AY8+BH8+BQ8+BZ8+CI8+CR8+DA8+DJ8+DS8+EB8+EK8+ET8+FC8+FL8+FU8+GD8+GM8+GV8+HE8+HN8+HW8+IF8+IO8+IX8+JG8+JP8+JY8+KH8+KQ8+KZ8+LI8+LR8+MA8+MJ8+MS8+NB8+NK8+NT8+OC8+OL8+OU8+PD8+PM8+PV8+QE8+QN8) -> 0 | QU8: =SUM(G8+P8+Y8+AH8+AQ8+AZ8+BI8+BR8+CA8+CJ8+CS8+DB8+DK8+DT8+EC8+EL8+EU8+FD8+FM8+FV8+GE8+GN8+GW8+HF8+HO8+HX8+IG8+IP8+IY8+JH8+JQ8+JZ8+KI8+KR8+LA8+LJ8+LS8+MB8+MK8+MT8+NC8+NL8+NU8+OD8+OM8+OV8+PE8+PN8+PW8+QF8+QO8) -> 4 | QV8: =SUM(H8+Q8+Z8+AI8+AR8+BA8+BJ8+BS8+CB8+CK8+CT8+DC8+DL8+DU8+ED8+EM8+EV8+FE8+FN8+FW8+GF8+GO8+GX8+HG8+HP8+HY8+IH8+IQ8+IZ8+JI8+JR8+KA8+KJ8+KS8+LB8+LK8+LT8+MC8+ML8+MU8+ND8+NM8+NV8+OE8+ON8+OW8+PF8+PO8+PX8+QG8+QP8) -> 30 | QW8: =SUM(I8+R8+AA8+AJ8+AS8+BB8+BK8+BT8+CC8+CL8+CU8+DD8+DM8+DV8+EE8+EN8+EW8+FF8+FO8+FX8+GG8+GP8+GY8+HH8+HQ8+HZ8+II8+IR8+JA8+JJ8+JS8+KB8+KK8+KT8+LC8+LL8+LU8+MD8+MM8+MV8+NE8+NN8+NW8+OF8+OO8+OX8+PG8+PP8+PY8+QH8+QQ8) -> 19 | QY8: =SUM(J8,S8,AB8,AK8,AT8,BC8,BL8,BU8,CD8,CM8,CV8,DE8,DN8,DW8,EF8,EO8,FP8,FY8,GH8,GQ8,HI8,HR8,IS8,JB8,JK8,JT8,KC8,KL8,KU8,LD8,LM8,LV8,ME8,MN8,MW8,NF8,NO8,NX8,OG8,OP8,OY8,PH8,PZ8)/5 -> 7 | RA8: =MAX(C8,L8,AD8,AM8,AV8,BN8,BW8,CF8,CX8,DG8,DP8,DY8,EH8,FI8,FR8,GA8,GJ8,HK8,IL8,IU8,JD8,JM8,JV8,KE8,KW8,LO8,LX8,MG8,MP8,MY8,NH8,NQ8,OI8,PA8,PS8) -> 18 | RB8: =MAX(D8,M8,AE8,AN8,AW8,BO8,BX8,CG8,CY8,DH8,DQ8,DZ8,EI8,FJ8,FS8,GB8,GK8,HL8,IM8,IV8,JE8,JN8,JW8,KF8,KX8,LP8,LY8,MH8,MQ8,MZ8,NI8,NR8,OJ8,PB8,PT8) -> 17 | RC8: =MAX(E8,N8,AF8,AO8,AX8,BP8,BY8,CH8,CZ8,DI8,DR8,EA8,EJ8,FK8,FT8,GC8,GL8,HM8,IN8,IW8,JF8,JO8,JX8,KG8,KY8,LQ8,LZ8,MI8,MR8,NA8,NJ8,NS8,OK8,PC8,PU8) -> 33 | RD8: =MIN(C8,L8,AD8,AM8,AV8,BN8,BW8,CF8,CX8,DG8,DP8,DY8,EH8,FI8,FR8,GA8,GJ8,HK8,IL8,IU8,JD8,JM8,JV8,KE8,KW8,LO8,LX8,MG8,MP8,MY8,NH8,NQ8,OI8,PA8,PS8) -> 9 | RE8: =MIN(D8,M8,AE8,AN8,AW8,BO8,BX8,CG8,CY8,DH8,DQ8,DZ8,EI8,FJ8,FS8,GB8,GK8,HL8,IM8,IV8,JE8,JN8,JW8,KF8,KX8,LP8,LY8,MH8,MQ8,MZ8,NI8,NR8,OJ8,PB8,PT8) -> 9 | RF8: =MIN(E8,N8,AF8,AO8,AX8,BP8,BY8,CH8,CZ8,DI8,DR8,EA8,EJ8,FK8,FT8,GC8,GL8,HM8,IN8,IW8,JF8,JO8,JX8,KG8,KY8,LQ8,LZ8,MI8,MR8,NA8,NJ8,NS8,OK8,PC8,PU8) -> 26 | RH8: =MAX(W8,BG8,CQ8,HD8,LH8,OB8,OT8) -> 34 | RI8: =MIN(W8,BG8,CQ8,HD8,LH8,OB8,OT8) -> 25 | RK8: =IFERROR(SUM(E8,N8,W8,AF8,AO8,AX8,BG8,BP8,BY8,CH8,CQ8,CZ8,DI8,DR8,EA8,EJ8,FK8,GC8,GL8,HD8,HM8,IN8,IW8,JF8,JO8,JX8,KG8,KY8,LH8,LQ8,LZ8,MI8,MR8,NA8,NJ8,NS8,OB8,OK8,OT8,PC8,)/QY8,0) -> 28.571429 | RM8: =MAX(ES8,IE8) -> 0 | RN8: =MIN(ES8,IE8) -> 0 | RP8: =SUM(EX8,IJ8)/5 -> 0
A9: ='Name List'!B9 -> Chris Burroughs | E9: =IF(C9=0,"",C9+D9) | J9: =IF(E9="","",'Name List'!$I$4) | U9: 18 | V9: 18 | W9: =IF(U9=0,"",U9+V9) -> 36 | X9: 0 | Y9: 2 | Z9: 9 | AA9: 0 | AB9: =IF(W9="","",'Name List'!$I$4) -> 5 | AF9: =IF(AD9=0,"",AD9+AE9) | AK9: =IF(AF9="","",'Name List'!$I$4) | AO9: =IF(AM9=0,"",AM9+AN9) | AT9: =IF(AO9="","",'Name List'!$I$4) | AX9: =IF(AV9=0,"",AV9+AW9) | BC9: =IF(AX9="","",'Name List'!$I$4) | BG9: =IF(BE9=0,"",BE9+BF9) | BL9: =IF(BG9="","",'Name List'!$I$4) | BY9: =IF(BW9=0,"",BW9+BX9) | CD9: =IF(BY9="","",'Name List'!$I$4) | CH9: =IF(CF9=0,"",CF9+CG9) | CM9: =IF(CH9="","",'Name List'!$I$4) | CQ9: =IF(CO9=0,"",CO9+CP9) | CV9: =IF(CQ9="","",'Name List'!$I$4) | CZ9: =IF(CX9=0,"",CX9+CY9) | DE9: =IF(CZ9="","",'Name List'!$I$4) | DI9: =IF(DG9=0,"",DG9+DH9) | DN9: =IF(DI9="","",'Name List'!$I$4) | DR9: =IF(DP9=0,"",DP9+DQ9) | DW9: =IF(DR9="","",'Name List'!$I$4) | EA9: =IF(DY9=0,"",DY9+DZ9) | EF9: =IF(EA9="","",'Name List'!$I$4) | EJ9: =IF(EH9=0,"",EH9+EI9) | EO9: =IF(EJ9="","",'Name List'!$I$4) | EX9: =IF(ES9="","",'Name List'!$I$4) | FI9: 16 | FJ9: 13 | FK9: =IF(FI9=0,"",FI9+FJ9) -> 29 | FL9: 0 | FM9: 0 | FN9: 8 | FO9: 2 | FP9: =IF(FK9="","",'Name List'!$I$4) -> 5 | FT9: =IF(FR9=0,"",FR9+FS9) | FY9: =IF(FT9="","",'Name List'!$I$4) | GC9: =IF(GA9=0,"",GA9+GB9) | GH9: =IF(GC9="","",'Name List'!$I$4) | GL9: =IF(GJ9=0,"",GJ9+GK9) | GQ9: =IF(GL9="","",'Name List'!$I$4) | HD9: =IF(HB9=0,"",HB9+HC9) | HI9: =IF(HD9="","",'Name List'!$I$4) | HM9: =IF(HK9=0,"",HK9+HL9) | HR9: =IF(HM9="","",'Name List'!$I$4) | IJ9: =IF(IE9="","",'Name List'!$I$4) | QR9: =IF(QM9="","",'Name List'!$I$4) | QT9: =SUM(F9+O9+X9+AG9+AP9+AY9+BH9+BQ9+BZ9+CI9+CR9+DA9+DJ9+DS9+EB9+EK9+ET9+FC9+FL9+FU9+GD9+GM9+GV9+HE9+HN9+HW9+IF9+IO9+IX9+JG9+JP9+JY9+KH9+KQ9+KZ9+LI9+LR9+MA9+MJ9+MS9+NB9+NK9+NT9+OC9+OL9+OU9+PD9+PM9+PV9+QE9+QN9) -> 0 | QU9: =SUM(G9+P9+Y9+AH9+AQ9+AZ9+BI9+BR9+CA9+CJ9+CS9+DB9+DK9+DT9+EC9+EL9+EU9+FD9+FM9+FV9+GE9+GN9+GW9+HF9+HO9+HX9+IG9+IP9+IY9+JH9+JQ9+JZ9+KI9+KR9+LA9+LJ9+LS9+MB9+MK9+MT9+NC9+NL9+NU9+OD9+OM9+OV9+PE9+PN9+PW9+QF9+QO9) -> 2 | QV9: =SUM(H9+Q9+Z9+AI9+AR9+BA9+BJ9+BS9+CB9+CK9+CT9+DC9+DL9+DU9+ED9+EM9+EV9+FE9+FN9+FW9+GF9+GO9+GX9+HG9+HP9+HY9+IH9+IQ9+IZ9+JI9+JR9+KA9+KJ9+KS9+LB9+LK9+LT9+MC9+ML9+MU9+ND9+NM9+NV9+OE9+ON9+OW9+PF9+PO9+PX9+QG9+QP9) -> 17 | QW9: =SUM(I9+R9+AA9+AJ9+AS9+BB9+BK9+BT9+CC9+CL9+CU9+DD9+DM9+DV9+EE9+EN9+EW9+FF9+FO9+FX9+GG9+GP9+GY9+HH9+HQ9+HZ9+II9+IR9+JA9+JJ9+JS9+KB9+KK9+KT9+LC9+LL9+LU9+MD9+MM9+MV9+NE9+NN9+NW9+OF9+OO9+OX9+PG9+PP9+PY9+QH9+QQ9) -> 2 | QY9: =SUM(J9,S9,AB9,AK9,AT9,BC9,BL9,BU9,CD9,CM9,CV9,DE9,DN9,DW9,EF9,EO9,FP9,FY9,GH9,GQ9,HI9,HR9,IS9,JB9,JK9,JT9,KC9,KL9,KU9,LD9,LM9,LV9,ME9,MN9,MW9,NF9,NO9,NX9,OG9,OP9,OY9,PH9,PZ9)/5 -> 2 | RA9: =MAX(C9,L9,AD9,AM9,AV9,BN9,BW9,CF9,CX9,DG9,DP9,DY9,EH9,FI9,FR9,GA9,GJ9,HK9,IL9,IU9,JD9,JM9,JV9,KE9,KW9,LO9,LX9,MG9,MP9,MY9,NH9,NQ9,OI9,PA9,PS9) -> 16 | RB9: =MAX(D9,M9,AE9,AN9,AW9,BO9,BX9,CG9,CY9,DH9,DQ9,DZ9,EI9,FJ9,FS9,GB9,GK9,HL9,IM9,IV9,JE9,JN9,JW9,KF9,KX9,LP9,LY9,MH9,MQ9,MZ9,NI9,NR9,OJ9,PB9,PT9) -> 13 | RC9: =MAX(E9,N9,AF9,AO9,AX9,BP9,BY9,CH9,CZ9,DI9,DR9,EA9,EJ9,FK9,FT9,GC9,GL9,HM9,IN9,IW9,JF9,JO9,JX9,KG9,KY9,LQ9,LZ9,MI9,MR9,NA9,NJ9,NS9,OK9,PC9,PU9) -> 29 | RD9: =MIN(C9,L9,AD9,AM9,AV9,BN9,BW9,CF9,CX9,DG9,DP9,DY9,EH9,FI9,FR9,GA9,GJ9,HK9,IL9,IU9,JD9,JM9,JV9,KE9,KW9,LO9,LX9,MG9,MP9,MY9,NH9,NQ9,OI9,PA9,PS9) -> 16 | RE9: =MIN(D9,M9,AE9,AN9,AW9,BO9,BX9,CG9,CY9,DH9,DQ9,DZ9,EI9,FJ9,FS9,GB9,GK9,HL9,IM9,IV9,JE9,JN9,JW9,KF9,KX9,LP9,LY9,MH9,MQ9,MZ9,NI9,NR9,OJ9,PB9,PT9) -> 13 | RF9: =MIN(E9,N9,AF9,AO9,AX9,BP9,BY9,CH9,CZ9,DI9,DR9,EA9,EJ9,FK9,FT9,GC9,GL9,HM9,IN9,IW9,JF9,JO9,JX9,KG9,KY9,LQ9,LZ9,MI9,MR9,NA9,NJ9,NS9,OK9,PC9,PU9) -> 29 | RH9: =MAX(W9,BG9,CQ9,HD9,LH9,OB9,OT9) -> 36 | RI9: =MIN(W9,BG9,CQ9,HD9,LH9,OB9,OT9) -> 36 | RK9: =IFERROR(SUM(E9,N9,W9,AF9,AO9,AX9,BG9,BP9,BY9,CH9,CQ9,CZ9,DI9,DR9,EA9,EJ9,FK9,GC9,GL9,HD9,HM9,IN9,IW9,JF9,JO9,JX9,KG9,KY9,LH9,LQ9,LZ9,MI9,MR9,NA9,NJ9,NS9,OB9,OK9,OT9,PC9,)/QY9,0) -> 32.5 | RM9: =MAX(ES9,IE9) -> 0 | RN9: =MIN(ES9,IE9) -> 0 | RP9: =SUM(EX9,IJ9)/5 -> 0
A10: ='Name List'!B10 -> George Burton | E10: =IF(C10=0,"",C10+D10) | J10: =IF(E10="","",'Name List'!$I$4) | W10: =IF(U10=0,"",U10+V10) | AB10: =IF(W10="","",'Name List'!$I$4) | AF10: =IF(AD10=0,"",AD10+AE10) | AK10: =IF(AF10="","",'Name List'!$I$4) | AO10: =IF(AM10=0,"",AM10+AN10) | AT10: =IF(AO10="","",'Name List'!$I$4) | AX10: =IF(AV10=0,"",AV10+AW10) | BC10: =IF(AX10="","",'Name List'!$I$4) | BG10: =IF(BE10=0,"",BE10+BF10) | BL10: =IF(BG10="","",'Name List'!$I$4) | BY10: =IF(BW10=0,"",BW10+BX10) | CD10: =IF(BY10="","",'Name List'!$I$4) | CF10: 13 | CG10: 14 | CH10: =IF(CF10=0,"",CF10+CG10) -> 27 | CI10: 0 | CJ10: 2 | CK10: 6 | CL10: 1 | CM10: =IF(CH10="","",'Name List'!$I$4) -> 5 | CO10: 13 | CP10: 16 | CQ10: =IF(CO10=0,"",CO10+CP10) -> 29 | CR10: 0 | CS10: 3 | CT10: 8 | CU10: 1 | CV10: =IF(CQ10="","",'Name List'!$I$4) -> 5 | CZ10: =IF(CX10=0,"",CX10+CY10) | DE10: =IF(CZ10="","",'Name List'!$I$4) | DI10: =IF(DG10=0,"",DG10+DH10) | DN10: =IF(DI10="","",'Name List'!$I$4) | DR10: =IF(DP10=0,"",DP10+DQ10) | DW10: =IF(DR10="","",'Name List'!$I$4) | EA10: =IF(DY10=0,"",DY10+DZ10) | EF10: =IF(EA10="","",'Name List'!$I$4) | EJ10: =IF(EH10=0,"",EH10+EI10) | EO10: =IF(EJ10="","",'Name List'!$I$4) | EX10: =IF(ES10="","",'Name List'!$I$4) | FK10: =IF(FI10=0,"",FI10+FJ10) | FP10: =IF(FK10="","",'Name List'!$I$4) | FT10: =IF(FR10=0,"",FR10+FS10) | FY10: =IF(FT10="","",'Name List'!$I$4) | GC10: =IF(GA10=0,"",GA10+GB10) | GH10: =IF(GC10="","",'Name List'!$I$4) | GL10: =IF(GJ10=0,"",GJ10+GK10) | GQ10: =IF(GL10="","",'Name List'!$I$4) | HD10: =IF(HB10=0,"",HB10+HC10) | HI10: =IF(HD10="","",'Name List'!$I$4) | HM10: =IF(HK10=0,"",HK10+HL10) | HR10: =IF(HM10="","",'Name List'!$I$4) | IJ10: =IF(IE10="","",'Name List'!$I$4) | QR10: =IF(QM10="","",'Name List'!$I$4) | QT10: =SUM(F10+O10+X10+AG10+AP10+AY10+BH10+BQ10+BZ10+CI10+CR10+DA10+DJ10+DS10+EB10+EK10+ET10+FC10+FL10+FU10+GD10+GM10+GV10+HE10+HN10+HW10+IF10+IO10+IX10+JG10+JP10+JY10+KH10+KQ10+KZ10+LI10+LR10+MA10+MJ10+MS10+NB10+NK10+NT10+OC10+OL10+OU10+PD10+PM10+PV10+QE10+QN10) -> 0 | QU10: =SUM(G10+P10+Y10+AH10+AQ10+AZ10+BI10+BR10+CA10+CJ10+CS10+DB10+DK10+DT10+EC10+EL10+EU10+FD10+FM10+FV10+GE10+GN10+GW10+HF10+HO10+HX10+IG10+IP10+IY10+JH10+JQ10+JZ10+KI10+KR10+LA10+LJ10+LS10+MB10+MK10+MT10+NC10+NL10+NU10+OD10+OM10+OV10+PE10+PN10+PW10+QF10+QO10) -> 5 | QV10: =SUM(H10+Q10+Z10+AI10+AR10+BA10+BJ10+BS10+CB10+CK10+CT10+DC10+DL10+DU10+ED10+EM10+EV10+FE10+FN10+FW10+GF10+GO10+GX10+HG10+HP10+HY10+IH10+IQ10+IZ10+JI10+JR10+KA10+KJ10+KS10+LB10+LK10+LT10+MC10+ML10+MU10+ND10+NM10+NV10+OE10+ON10+OW10+PF10+PO10+PX10+QG10+QP10) -> 14 | QW10: =SUM(I10+R10+AA10+AJ10+AS10+BB10+BK10+BT10+CC10+CL10+CU10+DD10+DM10+DV10+EE10+EN10+EW10+FF10+FO10+FX10+GG10+GP10+GY10+HH10+HQ10+HZ10+II10+IR10+JA10+JJ10+JS10+KB10+KK10+KT10+LC10+LL10+LU10+MD10+MM10+MV10+NE10+NN10+NW10+OF10+OO10+OX10+PG10+PP10+PY10+QH10+QQ10) -> 2 | QY10: =SUM(J10,S10,AB10,AK10,AT10,BC10,BL10,BU10,CD10,CM10,CV10,DE10,DN10,DW10,EF10,EO10,FP10,FY10,GH10,GQ10,HI10,HR10,IS10,JB10,JK10,JT10,KC10,KL10,KU10,LD10,LM10,LV10,ME10,MN10,MW10,NF10,NO10,NX10,OG10,OP10,OY10,PH10,PZ10)/5 -> 2 | RA10: =MAX(C10,L10,AD10,AM10,AV10,BN10,BW10,CF10,CX10,DG10,DP10,DY10,EH10,FI10,FR10,GA10,GJ10,HK10,IL10,IU10,JD10,JM10,JV10,KE10,KW10,LO10,LX10,MG10,MP10,MY10,NH10,NQ10,OI10,PA10,PS10) -> 13 | RB10: =MAX(D10,M10,AE10,AN10,AW10,BO10,BX10,CG10,CY10,DH10,DQ10,DZ10,EI10,FJ10,FS10,GB10,GK10,HL10,IM10,IV10,JE10,JN10,JW10,KF10,KX10,LP10,LY10,MH10,MQ10,MZ10,NI10,NR10,OJ10,PB10,PT10) -> 14 | RC10: =MAX(E10,N10,AF10,AO10,AX10,BP10,BY10,CH10,CZ10,DI10,DR10,EA10,EJ10,FK10,FT10,GC10,GL10,HM10,IN10,IW10,JF10,JO10,JX10,KG10,KY10,LQ10,LZ10,MI10,MR10,NA10,NJ10,NS10,OK10,PC10,PU10) -> 27 | RD10: =MIN(C10,L10,AD10,AM10,AV10,BN10,BW10,CF10,CX10,DG10,DP10,DY10,EH10,FI10,FR10,GA10,GJ10,HK10,IL10,IU10,JD10,JM10,JV10,KE10,KW10,LO10,LX10,MG10,MP10,MY10,NH10,NQ10,OI10,PA10,PS10) -> 13 | RE10: =MIN(D10,M10,AE10,AN10,AW10,BO10,BX10,CG10,CY10,DH10,DQ10,DZ10,EI10,FJ10,FS10,GB10,GK10,HL10,IM10,IV10,JE10,JN10,JW10,KF10,KX10,LP10,LY10,MH10,MQ10,MZ10,NI10,NR10,OJ10,PB10,PT10) -> 14 | RF10: =MIN(E10,N10,AF10,AO10,AX10,BP10,BY10,CH10,CZ10,DI10,DR10,EA10,EJ10,FK10,FT10,GC10,GL10,HM10,IN10,IW10,JF10,JO10,JX10,KG10,KY10,LQ10,LZ10,MI10,MR10,NA10,NJ10,NS10,OK10,PC10,PU10) -> 27 | RH10: =MAX(W10,BG10,CQ10,HD10,LH10,OB10,OT10) -> 29 | RI10: =MIN(W10,BG10,CQ10,HD10,LH10,OB10,OT10) -> 29 | RK10: =IFERROR(SUM(E10,N10,W10,AF10,AO10,AX10,BG10,BP10,BY10,CH10,CQ10,CZ10,DI10,DR10,EA10,EJ10,FK10,GC10,GL10,HD10,HM10,IN10,IW10,JF10,JO10,JX10,KG10,KY10,LH10,LQ10,LZ10,MI10,MR10,NA10,NJ10,NS10,OB10,OK10,OT10,PC10,)/QY10,0) -> 28 | RM10: =MAX(ES10,IE10) -> 0 | RN10: =MIN(ES10,IE10) -> 0 | RP10: =SUM(EX10,IJ10)/5 -> 0
A11: ='Name List'!B11 -> Tom Burton | E11: =IF(C11=0,"",C11+D11) | J11: =IF(E11="","",'Name List'!$I$4) | W11: =IF(U11=0,"",U11+V11) | AB11: =IF(W11="","",'Name List'!$I$4) | AF11: =IF(AD11=0,"",AD11+AE11) | AK11: =IF(AF11="","",'Name List'!$I$4) | AO11: =IF(AM11=0,"",AM11+AN11) | AT11: =IF(AO11="","",'Name List'!$I$4) | AV11: 15 | AW11: 15 | AX11: =IF(AV11=0,"",AV11+AW11) -> 30 | AY11: 0 | AZ11: 1 | BA11: 10 | BB11: 2 | BC11: =IF(AX11="","",'Name List'!$I$4) -> 5 | BG11: =IF(BE11=0,"",BE11+BF11) | BL11: =IF(BG11="","",'Name List'!$I$4) | BY11: =IF(BW11=0,"",BW11+BX11) | CD11: =IF(BY11="","",'Name List'!$I$4) | CF11: 16 | CG11: 13 | CH11: =IF(CF11=0,"",CF11+CG11) -> 29 | CI11: 0 | CJ11: 1 | CK11: 10 | CL11: 2 | CM11: =IF(CH11="","",'Name List'!$I$4) -> 5 | CO11: 15 | CP11: 18 | CQ11: =IF(CO11=0,"",CO11+CP11) -> 33 | CR11: 0 | CS11: 2 | CT11: 11 | CU11: 2 | CV11: =IF(CQ11="","",'Name List'!$I$4) -> 5 | CZ11: =IF(CX11=0,"",CX11+CY11) | DE11: =IF(CZ11="","",'Name List'!$I$4) | DI11: =IF(DG11=0,"",DG11+DH11) | DN11: =IF(DI11="","",'Name List'!$I$4) | DP11: 17 | DQ11: 19 | DR11: =IF(DP11=0,"",DP11+DQ11) -> 36 | DS11: 0 | DT11: 4 | DU11: 9 | DV11: 1 | DW11: =IF(DR11="","",'Name List'!$I$4) -> 5 | EA11: =IF(DY11=0,"",DY11+DZ11) | EF11: =IF(EA11="","",'Name List'!$I$4) | EJ11: =IF(EH11=0,"",EH11+EI11) | EO11: =IF(EJ11="","",'Name List'!$I$4) | EX11: =IF(ES11="","",'Name List'!$I$4) | FK11: =IF(FI11=0,"",FI11+FJ11) | FP11: =IF(FK11="","",'Name List'!$I$4) | FT11: =IF(FR11=0,"",FR11+FS11) | FY11: =IF(FT11="","",'Name List'!$I$4) | GC11: =IF(GA11=0,"",GA11+GB11) | GH11: =IF(GC11="","",'Name List'!$I$4) | GL11: =IF(GJ11=0,"",GJ11+GK11) | GQ11: =IF(GL11="","",'Name List'!$I$4) | HB11: 18 | HC11: 15 | HD11: =IF(HB11=0,"",HB11+HC11) -> 33 | HE11: 0 | HF11: 2 | HG11: 10 | HH11: 2 | HI11: =IF(HD11="","",'Name List'!$I$4) -> 5 | HM11: =IF(HK11=0,"",HK11+HL11) | HR11: =IF(HM11="","",'Name List'!$I$4) | IJ11: =IF(IE11="","",'Name List'!$I$4) | QR11: =IF(QM11="","",'Name List'!$I$4) | QT11: =SUM(F11+O11+X11+AG11+AP11+AY11+BH11+BQ11+BZ11+CI11+CR11+DA11+DJ11+DS11+EB11+EK11+ET11+FC11+FL11+FU11+GD11+GM11+GV11+HE11+HN11+HW11+IF11+IO11+IX11+JG11+JP11+JY11+KH11+KQ11+KZ11+LI11+LR11+MA11+MJ11+MS11+NB11+NK11+NT11+OC11+OL11+OU11+PD11+PM11+PV11+QE11+QN11) -> 0 | QU11: =SUM(G11+P11+Y11+AH11+AQ11+AZ11+BI11+BR11+CA11+CJ11+CS11+DB11+DK11+DT11+EC11+EL11+EU11+FD11+FM11+FV11+GE11+GN11+GW11+HF11+HO11+HX11+IG11+IP11+IY11+JH11+JQ11+JZ11+KI11+KR11+LA11+LJ11+LS11+MB11+MK11+MT11+NC11+NL11+NU11+OD11+OM11+OV11+PE11+PN11+PW11+QF11+QO11) -> 10 | QV11: =SUM(H11+Q11+Z11+AI11+AR11+BA11+BJ11+BS11+CB11+CK11+CT11+DC11+DL11+DU11+ED11+EM11+EV11+FE11+FN11+FW11+GF11+GO11+GX11+HG11+HP11+HY11+IH11+IQ11+IZ11+JI11+JR11+KA11+KJ11+KS11+LB11+LK11+LT11+MC11+ML11+MU11+ND11+NM11+NV11+OE11+ON11+OW11+PF11+PO11+PX11+QG11+QP11) -> 50 | QW11: =SUM(I11+R11+AA11+AJ11+AS11+BB11+BK11+BT11+CC11+CL11+CU11+DD11+DM11+DV11+EE11+EN11+EW11+FF11+FO11+FX11+GG11+GP11+GY11+HH11+HQ11+HZ11+II11+IR11+JA11+JJ11+JS11+KB11+KK11+KT11+LC11+LL11+LU11+MD11+MM11+MV11+NE11+NN11+NW11+OF11+OO11+OX11+PG11+PP11+PY11+QH11+QQ11) -> 9 | QY11: =SUM(J11,S11,AB11,AK11,AT11,BC11,BL11,BU11,CD11,CM11,CV11,DE11,DN11,DW11,EF11,EO11,FP11,FY11,GH11,GQ11,HI11,HR11,IS11,JB11,JK11,JT11,KC11,KL11,KU11,LD11,LM11,LV11,ME11,MN11,MW11,NF11,NO11,NX11,OG11,OP11,OY11,PH11,PZ11)/5 -> 5 | RA11: =MAX(C11,L11,AD11,AM11,AV11,BN11,BW11,CF11,CX11,DG11,DP11,DY11,EH11,FI11,FR11,GA11,GJ11,HK11,IL11,IU11,JD11,JM11,JV11,KE11,KW11,LO11,LX11,MG11,MP11,MY11,NH11,NQ11,OI11,PA11,PS11) -> 17 | RB11: =MAX(D11,M11,AE11,AN11,AW11,BO11,BX11,CG11,CY11,DH11,DQ11,DZ11,EI11,FJ11,FS11,GB11,GK11,HL11,IM11,IV11,JE11,JN11,JW11,KF11,KX11,LP11,LY11,MH11,MQ11,MZ11,NI11,NR11,OJ11,PB11,PT11) -> 19 | RC11: =MAX(E11,N11,AF11,AO11,AX11,BP11,BY11,CH11,CZ11,DI11,DR11,EA11,EJ11,FK11,FT11,GC11,GL11,HM11,IN11,IW11,JF11,JO11,JX11,KG11,KY11,LQ11,LZ11,MI11,MR11,NA11,NJ11,NS11,OK11,PC11,PU11) -> 36 | RD11: =MIN(C11,L11,AD11,AM11,AV11,BN11,BW11,CF11,CX11,DG11,DP11,DY11,EH11,FI11,FR11,GA11,GJ11,HK11,IL11,IU11,JD11,JM11,JV11,KE11,KW11,LO11,LX11,MG11,MP11,MY11,NH11,NQ11,OI11,PA11,PS11) -> 15 | RE11: =MIN(D11,M11,AE11,AN11,AW11,BO11,BX11,CG11,CY11,DH11,DQ11,DZ11,EI11,FJ11,FS11,GB11,GK11,HL11,IM11,IV11,JE11,JN11,JW11,KF11,KX11,LP11,LY11,MH11,MQ11,MZ11,NI11,NR11,OJ11,PB11,PT11) -> 13 | RF11: =MIN(E11,N11,AF11,AO11,AX11,BP11,BY11,CH11,CZ11,DI11,DR11,EA11,EJ11,FK11,FT11,GC11,GL11,HM11,IN11,IW11,JF11,JO11,JX11,KG11,KY11,LQ11,LZ11,MI11,MR11,NA11,NJ11,NS11,OK11,PC11,PU11) -> 29 | RH11: =MAX(W11,BG11,CQ11,HD11,LH11,OB11,OT11) -> 33 | RI11: =MIN(W11,BG11,CQ11,HD11,LH11,OB11,OT11) -> 33 | RK11: =IFERROR(SUM(E11,N11,W11,AF11,AO11,AX11,BG11,BP11,BY11,CH11,CQ11,CZ11,DI11,DR11,EA11,EJ11,FK11,GC11,GL11,HD11,HM11,IN11,IW11,JF11,JO11,JX11,KG11,KY11,LH11,LQ11,LZ11,MI11,MR11,NA11,NJ11,NS11,OB11,OK11,OT11,PC11,)/QY11,0) -> 32.2 | RM11: =MAX(ES11,IE11) -> 0 | RN11: =MIN(ES11,IE11) -> 0 | RP11: =SUM(EX11,IJ11)/5 -> 0
A12: ='Name List'!B12 -> Mike Chubb | E12: =IF(C12=0,"",C12+D12) | J12: =IF(E12="","",'Name List'!$I$4) | W12: =IF(U12=0,"",U12+V12) | AB12: =IF(W12="","",'Name List'!$I$4) | AF12: =IF(AD12=0,"",AD12+AE12) | AK12: =IF(AF12="","",'Name List'!$I$4) | AO12: =IF(AM12=0,"",AM12+AN12) | AT12: =IF(AO12="","",'Name List'!$I$4) | AX12: =IF(AV12=0,"",AV12+AW12) | BC12: =IF(AX12="","",'Name List'!$I$4) | BG12: =IF(BE12=0,"",BE12+BF12) | BL12: =IF(BG12="","",'Name List'!$I$4) | BY12: =IF(BW12=0,"",BW12+BX12) | CD12: =IF(BY12="","",'Name List'!$I$4) | CH12: =IF(CF12=0,"",CF12+CG12) | CM12: =IF(CH12="","",'Name List'!$I$4) | CQ12: =IF(CO12=0,"",CO12+CP12) | CV12: =IF(CQ12="","",'Name List'!$I$4) | CZ12: =IF(CX12=0,"",CX12+CY12) | DE12: =IF(CZ12="","",'Name List'!$I$4) | DI12: =IF(DG12=0,"",DG12+DH12) | DN12: =IF(DI12="","",'Name List'!$I$4) | DR12: =IF(DP12=0,"",DP12+DQ12) | DW12: =IF(DR12="","",'Name List'!$I$4) | EA12: =IF(DY12=0,"",DY12+DZ12) | EF12: =IF(EA12="","",'Name List'!$I$4) | EJ12: =IF(EH12=0,"",EH12+EI12) | EO12: =IF(EJ12="","",'Name List'!$I$4) | EX12: =IF(ES12="","",'Name List'!$I$4) | FI12: 17 | FJ12: 17 | FK12: =IF(FI12=0,"",FI12+FJ12) -> 34 | FL12: 0 | FM12: 0 | FN12: 3 | FO12: 2 | FP12: =IF(FK12="","",'Name List'!$I$4) -> 5 | FT12: =IF(FR12=0,"",FR12+FS12) | FY12: =IF(FT12="","",'Name List'!$I$4) | GC12: =IF(GA12=0,"",GA12+GB12) | GH12: =IF(GC12="","",'Name List'!$I$4) | GL12: =IF(GJ12=0,"",GJ12+GK12) | GQ12: =IF(GL12="","",'Name List'!$I$4) | HD12: =IF(HB12=0,"",HB12+HC12) | HI12: =IF(HD12="","",'Name List'!$I$4) | HM12: =IF(HK12=0,"",HK12+HL12) | HR12: =IF(HM12="","",'Name List'!$I$4) | IJ12: =IF(IE12="","",'Name List'!$I$4) | QR12: =IF(QM12="","",'Name List'!$I$4) | QT12: =SUM(F12+O12+X12+AG12+AP12+AY12+BH12+BQ12+BZ12+CI12+CR12+DA12+DJ12+DS12+EB12+EK12+ET12+FC12+FL12+FU12+GD12+GM12+GV12+HE12+HN12+HW12+IF12+IO12+IX12+JG12+JP12+JY12+KH12+KQ12+KZ12+LI12+LR12+MA12+MJ12+MS12+NB12+NK12+NT12+OC12+OL12+OU12+PD12+PM12+PV12+QE12+QN12) -> 0 | QU12: =SUM(G12+P12+Y12+AH12+AQ12+AZ12+BI12+BR12+CA12+CJ12+CS12+DB12+DK12+DT12+EC12+EL12+EU12+FD12+FM12+FV12+GE12+GN12+GW12+HF12+HO12+HX12+IG12+IP12+IY12+JH12+JQ12+JZ12+KI12+KR12+LA12+LJ12+LS12+MB12+MK12+MT12+NC12+NL12+NU12+OD12+OM12+OV12+PE12+PN12+PW12+QF12+QO12) -> 0 | QV12: =SUM(H12+Q12+Z12+AI12+AR12+BA12+BJ12+BS12+CB12+CK12+CT12+DC12+DL12+DU12+ED12+EM12+EV12+FE12+FN12+FW12+GF12+GO12+GX12+HG12+HP12+HY12+IH12+IQ12+IZ12+JI12+JR12+KA12+KJ12+KS12+LB12+LK12+LT12+MC12+ML12+MU12+ND12+NM12+NV12+OE12+ON12+OW12+PF12+PO12+PX12+QG12+QP12) -> 3 | QW12: =SUM(I12+R12+AA12+AJ12+AS12+BB12+BK12+BT12+CC12+CL12+CU12+DD12+DM12+DV12+EE12+EN12+EW12+FF12+FO12+FX12+GG12+GP12+GY12+HH12+HQ12+HZ12+II12+IR12+JA12+JJ12+JS12+KB12+KK12+KT12+LC12+LL12+LU12+MD12+MM12+MV12+NE12+NN12+NW12+OF12+OO12+OX12+PG12+PP12+PY12+QH12+QQ12) -> 2 | QY12: =SUM(J12,S12,AB12,AK12,AT12,BC12,BL12,BU12,CD12,CM12,CV12,DE12,DN12,DW12,EF12,EO12,FP12,FY12,GH12,GQ12,HI12,HR12,IS12,JB12,JK12,JT12,KC12,KL12,KU12,LD12,LM12,LV12,ME12,MN12,MW12,NF12,NO12,NX12,OG12,OP12,OY12,PH12,PZ12)/5 -> 1 | RA12: =MAX(C12,L12,AD12,AM12,AV12,BN12,BW12,CF12,CX12,DG12,DP12,DY12,EH12,FI12,FR12,GA12,GJ12,HK12,IL12,IU12,JD12,JM12,JV12,KE12,KW12,LO12,LX12,MG12,MP12,MY12,NH12,NQ12,OI12,PA12,PS12) -> 17 | RB12: =MAX(D12,M12,AE12,AN12,AW12,BO12,BX12,CG12,CY12,DH12,DQ12,DZ12,EI12,FJ12,FS12,GB12,GK12,HL12,IM12,IV12,JE12,JN12,JW12,KF12,KX12,LP12,LY12,MH12,MQ12,MZ12,NI12,NR12,OJ12,PB12,PT12) -> 17 | RC12: =MAX(E12,N12,AF12,AO12,AX12,BP12,BY12,CH12,CZ12,DI12,DR12,EA12,EJ12,FK12,FT12,GC12,GL12,HM12,IN12,IW12,JF12,JO12,JX12,KG12,KY12,LQ12,LZ12,MI12,MR12,NA12,NJ12,NS12,OK12,PC12,PU12) -> 34 | RD12: =MIN(C12,L12,AD12,AM12,AV12,BN12,BW12,CF12,CX12,DG12,DP12,DY12,EH12,FI12,FR12,GA12,GJ12,HK12,IL12,IU12,JD12,JM12,JV12,KE12,KW12,LO12,LX12,MG12,MP12,MY12,NH12,NQ12,OI12,PA12,PS12) -> 17 | RE12: =MIN(D12,M12,AE12,AN12,AW12,BO12,BX12,CG12,CY12,DH12,DQ12,DZ12,EI12,FJ12,FS12,GB12,GK12,HL12,IM12,IV12,JE12,JN12,JW12,KF12,KX12,LP12,LY12,MH12,MQ12,MZ12,NI12,NR12,OJ12,PB12,PT12) -> 17 | RF12: =MIN(E12,N12,AF12,AO12,AX12,BP12,BY12,CH12,CZ12,DI12,DR12,EA12,EJ12,FK12,FT12,GC12,GL12,HM12,IN12,IW12,JF12,JO12,JX12,KG12,KY12,LQ12,LZ12,MI12,MR12,NA12,NJ12,NS12,OK12,PC12,PU12) -> 34 | RH12: =MAX(W12,BG12,CQ12,HD12,LH12,OB12,OT12) -> 0 | RI12: =MIN(W12,BG12,CQ12,HD12,LH12,OB12,OT12) -> 0 | RK12: =IFERROR(SUM(E12,N12,W12,AF12,AO12,AX12,BG12,BP12,BY12,CH12,CQ12,CZ12,DI12,DR12,EA12,EJ12,FK12,GC12,GL12,HD12,HM12,IN12,IW12,JF12,JO12,JX12,KG12,KY12,LH12,LQ12,LZ12,MI12,MR12,NA12,NJ12,NS12,OB12,OK12,OT12,PC12,)/QY12,0) -> 34 | RM12: =MAX(ES12,IE12) -> 0 | RN12: =MIN(ES12,IE12) -> 0 | RP12: =SUM(EX12,IJ12)/5 -> 0
A13: ='Name List'!B13 -> George Clarke | E13: =IF(C13=0,"",C13+D13) | J13: =IF(E13="","",'Name List'!$I$4) | W13: =IF(U13=0,"",U13+V13) | AB13: =IF(W13="","",'Name List'!$I$4) | AF13: =IF(AD13=0,"",AD13+AE13) | AK13: =IF(AF13="","",'Name List'!$I$4) | AO13: =IF(AM13=0,"",AM13+AN13) | AT13: =IF(AO13="","",'Name List'!$I$4) | AX13: =IF(AV13=0,"",AV13+AW13) | BC13: =IF(AX13="","",'Name List'!$I$4) | BG13: =IF(BE13=0,"",BE13+BF13) | BL13: =IF(BG13="","",'Name List'!$I$4) | BY13: =IF(BW13=0,"",BW13+BX13) | CD13: =IF(BY13="","",'Name List'!$I$4) | CH13: =IF(CF13=0,"",CF13+CG13) | CM13: =IF(CH13="","",'Name List'!$I$4) | CQ13: =IF(CO13=0,"",CO13+CP13) | CV13: =IF(CQ13="","",'Name List'!$I$4) | CZ13: =IF(CX13=0,"",CX13+CY13) | DE13: =IF(CZ13="","",'Name List'!$I$4) | DI13: =IF(DG13=0,"",DG13+DH13) | DN13: =IF(DI13="","",'Name List'!$I$4) | DP13: 17 | DQ13: 18 | DR13: =IF(DP13=0,"",DP13+DQ13) -> 35 | DS13: 0 | DT13: 1 | DU13: 7 | DV13: 1 | DW13: =IF(DR13="","",'Name List'!$I$4) -> 5 | EA13: =IF(DY13=0,"",DY13+DZ13) | EF13: =IF(EA13="","",'Name List'!$I$4) | EJ13: =IF(EH13=0,"",EH13+EI13) | EO13: =IF(EJ13="","",'Name List'!$I$4) | EX13: =IF(ES13="","",'Name List'!$I$4) | FK13: =IF(FI13=0,"",FI13+FJ13) | FP13: =IF(FK13="","",'Name List'!$I$4) | FT13: =IF(FR13=0,"",FR13+FS13) | FY13: =IF(FT13="","",'Name List'!$I$4) | GC13: =IF(GA13=0,"",GA13+GB13) | GH13: =IF(GC13="","",'Name List'!$I$4) | GL13: =IF(GJ13=0,"",GJ13+GK13) | GQ13: =IF(GL13="","",'Name List'!$I$4) | HD13: =IF(HB13=0,"",HB13+HC13) | HI13: =IF(HD13="","",'Name List'!$I$4) | HM13: =IF(HK13=0,"",HK13+HL13) | HR13: =IF(HM13="","",'Name List'!$I$4) | IJ13: =IF(IE13="","",'Name List'!$I$4) | QR13: =IF(QM13="","",'Name List'!$I$4) | QT13: =SUM(F13+O13+X13+AG13+AP13+AY13+BH13+BQ13+BZ13+CI13+CR13+DA13+DJ13+DS13+EB13+EK13+ET13+FC13+FL13+FU13+GD13+GM13+GV13+HE13+HN13+HW13+IF13+IO13+IX13+JG13+JP13+JY13+KH13+KQ13+KZ13+LI13+LR13+MA13+MJ13+MS13+NB13+NK13+NT13+OC13+OL13+OU13+PD13+PM13+PV13+QE13+QN13) -> 0 | QU13: =SUM(G13+P13+Y13+AH13+AQ13+AZ13+BI13+BR13+CA13+CJ13+CS13+DB13+DK13+DT13+EC13+EL13+EU13+FD13+FM13+FV13+GE13+GN13+GW13+HF13+HO13+HX13+IG13+IP13+IY13+JH13+JQ13+JZ13+KI13+KR13+LA13+LJ13+LS13+MB13+MK13+MT13+NC13+NL13+NU13+OD13+OM13+OV13+PE13+PN13+PW13+QF13+QO13) -> 1 | QV13: =SUM(H13+Q13+Z13+AI13+AR13+BA13+BJ13+BS13+CB13+CK13+CT13+DC13+DL13+DU13+ED13+EM13+EV13+FE13+FN13+FW13+GF13+GO13+GX13+HG13+HP13+HY13+IH13+IQ13+IZ13+JI13+JR13+KA13+KJ13+KS13+LB13+LK13+LT13+MC13+ML13+MU13+ND13+NM13+NV13+OE13+ON13+OW13+PF13+PO13+PX13+QG13+QP13) -> 7 | QW13: =SUM(I13+R13+AA13+AJ13+AS13+BB13+BK13+BT13+CC13+CL13+CU13+DD13+DM13+DV13+EE13+EN13+EW13+FF13+FO13+FX13+GG13+GP13+GY13+HH13+HQ13+HZ13+II13+IR13+JA13+JJ13+JS13+KB13+KK13+KT13+LC13+LL13+LU13+MD13+MM13+MV13+NE13+NN13+NW13+OF13+OO13+OX13+PG13+PP13+PY13+QH13+QQ13) -> 1 | QY13: =SUM(J13,S13,AB13,AK13,AT13,BC13,BL13,BU13,CD13,CM13,CV13,DE13,DN13,DW13,EF13,EO13,FP13,FY13,GH13,GQ13,HI13,HR13,IS13,JB13,JK13,JT13,KC13,KL13,KU13,LD13,LM13,LV13,ME13,MN13,MW13,NF13,NO13,NX13,OG13,OP13,OY13,PH13,PZ13)/5 -> 1 | RA13: =MAX(C13,L13,AD13,AM13,AV13,BN13,BW13,CF13,CX13,DG13,DP13,DY13,EH13,FI13,FR13,GA13,GJ13,HK13,IL13,IU13,JD13,JM13,JV13,KE13,KW13,LO13,LX13,MG13,MP13,MY13,NH13,NQ13,OI13,PA13,PS13) -> 17 | RB13: =MAX(D13,M13,AE13,AN13,AW13,BO13,BX13,CG13,CY13,DH13,DQ13,DZ13,EI13,FJ13,FS13,GB13,GK13,HL13,IM13,IV13,JE13,JN13,JW13,KF13,KX13,LP13,LY13,MH13,MQ13,MZ13,NI13,NR13,OJ13,PB13,PT13) -> 18 | RC13: =MAX(E13,N13,AF13,AO13,AX13,BP13,BY13,CH13,CZ13,DI13,DR13,EA13,EJ13,FK13,FT13,GC13,GL13,HM13,IN13,IW13,JF13,JO13,JX13,KG13,KY13,LQ13,LZ13,MI13,MR13,NA13,NJ13,NS13,OK13,PC13,PU13) -> 35 | RD13: =MIN(C13,L13,AD13,AM13,AV13,BN13,BW13,CF13,CX13,DG13,DP13,DY13,EH13,FI13,FR13,GA13,GJ13,HK13,IL13,IU13,JD13,JM13,JV13,KE13,KW13,LO13,LX13,MG13,MP13,MY13,NH13,NQ13,OI13,PA13,PS13) -> 17 | RE13: =MIN(D13,M13,AE13,AN13,AW13,BO13,BX13,CG13,CY13,DH13,DQ13,DZ13,EI13,FJ13,FS13,GB13,GK13,HL13,IM13,IV13,JE13,JN13,JW13,KF13,KX13,LP13,LY13,MH13,MQ13,MZ13,NI13,NR13,OJ13,PB13,PT13) -> 18 | RF13: =MIN(E13,N13,AF13,AO13,AX13,BP13,BY13,CH13,CZ13,DI13,DR13,EA13,EJ13,FK13,FT13,GC13,GL13,HM13,IN13,IW13,JF13,JO13,JX13,KG13,KY13,LQ13,LZ13,MI13,MR13,NA13,NJ13,NS13,OK13,PC13,PU13) -> 35 | RH13: =MAX(W13,BG13,CQ13,HD13,LH13,OB13,OT13) -> 0 | RI13: =MIN(W13,BG13,CQ13,HD13,LH13,OB13,OT13) -> 0 | RK13: =IFERROR(SUM(E13,N13,W13,AF13,AO13,AX13,BG13,BP13,BY13,CH13,CQ13,CZ13,DI13,DR13,EA13,EJ13,FK13,GC13,GL13,HD13,HM13,IN13,IW13,JF13,JO13,JX13,KG13,KY13,LH13,LQ13,LZ13,MI13,MR13,NA13,NJ13,NS13,OB13,OK13,OT13,PC13,)/QY13,0) -> 35 | RM13: =MAX(ES13,IE13) -> 0 | RN13: =MIN(ES13,IE13) -> 0 | RP13: =SUM(EX13,IJ13)/5 -> 0
A14: ='Name List'!B14 -> Paul Clarke | E14: =IF(C14=0,"",C14+D14) | J14: =IF(E14="","",'Name List'!$I$4) | W14: =IF(U14=0,"",U14+V14) | AB14: =IF(W14="","",'Name List'!$I$4) | AD14: 16 | AE14: 18 | AF14: =IF(AD14=0,"",AD14+AE14) -> 34 | AG14: 0 | AH14: 0 | AI14: 7 | AJ14: 1 | AK14: =IF(AF14="","",'Name List'!$I$4) -> 5 | AM14: 21 | AN14: 16 | AO14: =IF(AM14=0,"",AM14+AN14) -> 37 | AP14: 0 | AQ14: 3 | AR14: 3 | AS14: 0 | AT14: =IF(AO14="","",'Name List'!$I$4) -> 5 | AX14: =IF(AV14=0,"",AV14+AW14) | BC14: =IF(AX14="","",'Name List'!$I$4) | BE14: 17 | BF14: 14 | BG14: =IF(BE14=0,"",BE14+BF14) -> 31 | BH14: 0 | BI14: 0 | BJ14: 4 | BK14: 1 | BL14: =IF(BG14="","",'Name List'!$I$4) -> 5 | BY14: =IF(BW14=0,"",BW14+BX14) | CD14: =IF(BY14="","",'Name List'!$I$4) | CH14: =IF(CF14=0,"",CF14+CG14) | CM14: =IF(CH14="","",'Name List'!$I$4) | CQ14: =IF(CO14=0,"",CO14+CP14) | CV14: =IF(CQ14="","",'Name List'!$I$4) | CX14: 16 | CY14: 15 | CZ14: =IF(CX14=0,"",CX14+CY14) -> 31 | DA14: 0 | DB14: 1 | DC14: 6 | DD14: 1 | DE14: =IF(CZ14="","",'Name List'!$I$4) -> 5 | DG14: 12 | DH14: 10 | DI14: =IF(DG14=0,"",DG14+DH14) -> 22 | DJ14: 0 | DK14: 0 | DL14: 4 | DM14: 7 | DN14: =IF(DI14="","",'Name List'!$I$4) -> 5 | DP14: 17 | DQ14: 11 | DR14: =IF(DP14=0,"",DP14+DQ14) -> 28 | DS14: 0 | DT14: 0 | DU14: 6 | DV14: 2 | DW14: =IF(DR14="","",'Name List'!$I$4) -> 5 | EA14: =IF(DY14=0,"",DY14+DZ14) | EF14: =IF(EA14="","",'Name List'!$I$4) | EH14: 14 | EI14: 16 | EJ14: =IF(EH14=0,"",EH14+EI14) -> 30 | EK14: 0 | EL14: 1 | EM14: 3 | EN14: 0 | EO14: =IF(EJ14="","",'Name List'!$I$4) -> 5 | EX14: =IF(ES14="","",'Name List'!$I$4) | FK14: =IF(FI14=0,"",FI14+FJ14) | FP14: =IF(FK14="","",'Name List'!$I$4) | FR14: 15 | FS14: 4 | FT14: =IF(FR14=0,"",FR14+FS14) -> 19 | FU14: 0 | FV14: 0 | FW14: 3 | FX14: 6 | FY14: =IF(FT14="","",'Name List'!$I$4) -> 5 | GC14: =IF(GA14=0,"",GA14+GB14) | GH14: =IF(GC14="","",'Name List'!$I$4) | GL14: =IF(GJ14=0,"",GJ14+GK14) | GQ14: =IF(GL14="","",'Name List'!$I$4) | HD14: =IF(HB14=0,"",HB14+HC14) | HI14: =IF(HD14="","",'Name List'!$I$4) | HM14: =IF(HK14=0,"",HK14+HL14) | HR14: =IF(HM14="","",'Name List'!$I$4) | IJ14: =IF(IE14="","",'Name List'!$I$4) | QR14: =IF(QM14="","",'Name List'!$I$4) | QT14: =SUM(F14+O14+X14+AG14+AP14+AY14+BH14+BQ14+BZ14+CI14+CR14+DA14+DJ14+DS14+EB14+EK14+ET14+FC14+FL14+FU14+GD14+GM14+GV14+HE14+HN14+HW14+IF14+IO14+IX14+JG14+JP14+JY14+KH14+KQ14+KZ14+LI14+LR14+MA14+MJ14+MS14+NB14+NK14+NT14+OC14+OL14+OU14+PD14+PM14+PV14+QE14+QN14) -> 0 | QU14: =SUM(G14+P14+Y14+AH14+AQ14+AZ14+BI14+BR14+CA14+CJ14+CS14+DB14+DK14+DT14+EC14+EL14+EU14+FD14+FM14+FV14+GE14+GN14+GW14+HF14+HO14+HX14+IG14+IP14+IY14+JH14+JQ14+JZ14+KI14+KR14+LA14+LJ14+LS14+MB14+MK14+MT14+NC14+NL14+NU14+OD14+OM14+OV14+PE14+PN14+PW14+QF14+QO14) -> 5 | QV14: =SUM(H14+Q14+Z14+AI14+AR14+BA14+BJ14+BS14+CB14+CK14+CT14+DC14+DL14+DU14+ED14+EM14+EV14+FE14+FN14+FW14+GF14+GO14+GX14+HG14+HP14+HY14+IH14+IQ14+IZ14+JI14+JR14+KA14+KJ14+KS14+LB14+LK14+LT14+MC14+ML14+MU14+ND14+NM14+NV14+OE14+ON14+OW14+PF14+PO14+PX14+QG14+QP14) -> 36 | QW14: =SUM(I14+R14+AA14+AJ14+AS14+BB14+BK14+BT14+CC14+CL14+CU14+DD14+DM14+DV14+EE14+EN14+EW14+FF14+FO14+FX14+GG14+GP14+GY14+HH14+HQ14+HZ14+II14+IR14+JA14+JJ14+JS14+KB14+KK14+KT14+LC14+LL14+LU14+MD14+MM14+MV14+NE14+NN14+NW14+OF14+OO14+OX14+PG14+PP14+PY14+QH14+QQ14) -> 18 | QY14: =SUM(J14,S14,AB14,AK14,AT14,BC14,BL14,BU14,CD14,CM14,CV14,DE14,DN14,DW14,EF14,EO14,FP14,FY14,GH14,GQ14,HI14,HR14,IS14,JB14,JK14,JT14,KC14,KL14,KU14,LD14,LM14,LV14,ME14,MN14,MW14,NF14,NO14,NX14,OG14,OP14,OY14,PH14,PZ14)/5 -> 8 | RA14: =MAX(C14,L14,AD14,AM14,AV14,BN14,BW14,CF14,CX14,DG14,DP14,DY14,EH14,FI14,FR14,GA14,GJ14,HK14,IL14,IU14,JD14,JM14,JV14,KE14,KW14,LO14,LX14,MG14,MP14,MY14,NH14,NQ14,OI14,PA14,PS14) -> 21 | RB14: =MAX(D14,M14,AE14,AN14,AW14,BO14,BX14,CG14,CY14,DH14,DQ14,DZ14,EI14,FJ14,FS14,GB14,GK14,HL14,IM14,IV14,JE14,JN14,JW14,KF14,KX14,LP14,LY14,MH14,MQ14,MZ14,NI14,NR14,OJ14,PB14,PT14) -> 18 | RC14: =MAX(E14,N14,AF14,AO14,AX14,BP14,BY14,CH14,CZ14,DI14,DR14,EA14,EJ14,FK14,FT14,GC14,GL14,HM14,IN14,IW14,JF14,JO14,JX14,KG14,KY14,LQ14,LZ14,MI14,MR14,NA14,NJ14,NS14,OK14,PC14,PU14) -> 37 | RD14: =MIN(C14,L14,AD14,AM14,AV14,BN14,BW14,CF14,CX14,DG14,DP14,DY14,EH14,FI14,FR14,GA14,GJ14,HK14,IL14,IU14,JD14,JM14,JV14,KE14,KW14,LO14,LX14,MG14,MP14,MY14,NH14,NQ14,OI14,PA14,PS14) -> 12 | RE14: =MIN(D14,M14,AE14,AN14,AW14,BO14,BX14,CG14,CY14,DH14,DQ14,DZ14,EI14,FJ14,FS14,GB14,GK14,HL14,IM14,IV14,JE14,JN14,JW14,KF14,KX14,LP14,LY14,MH14,MQ14,MZ14,NI14,NR14,OJ14,PB14,PT14) -> 4 | RF14: =MIN(E14,N14,AF14,AO14,AX14,BP14,BY14,CH14,CZ14,DI14,DR14,EA14,EJ14,FK14,FT14,GC14,GL14,HM14,IN14,IW14,JF14,JO14,JX14,KG14,KY14,LQ14,LZ14,MI14,MR14,NA14,NJ14,NS14,OK14,PC14,PU14) -> 19 | RH14: =MAX(W14,BG14,CQ14,HD14,LH14,OB14,OT14) -> 31 | RI14: =MIN(W14,BG14,CQ14,HD14,LH14,OB14,OT14) -> 31 | RK14: =IFERROR(SUM(E14,N14,W14,AF14,AO14,AX14,BG14,BP14,BY14,CH14,CQ14,CZ14,DI14,DR14,EA14,EJ14,FK14,GC14,GL14,HD14,HM14,IN14,IW14,JF14,JO14,JX14,KG14,KY14,LH14,LQ14,LZ14,MI14,MR14,NA14,NJ14,NS14,OB14,OK14,OT14,PC14,)/QY14,0) -> 26.625 | RM14: =MAX(ES14,IE14) -> 0 | RN14: =MIN(ES14,IE14) -> 0 | RP14: =SUM(EX14,IJ14)/5 -> 0
